Workbook

Sheet CB_DATA_
A1: Crystal Ball Data
A3: Workbook Variables | B3: Last Var Column | C3: 0
A4: Name:
A5: Value:
A7: Worksheet Data | B7: Last Data Column Used
B8: 2
A10: Sheet Ref
A11: =CB_DATA_!#REF! -> #REF! | B11: =Plan1!#REF! -> #REF!
A13: Sheet Guid
A14: 754c0266-1818-48d2-b57b-31a1311b4cc0 | B14: 2f45e38c-30fd-4235-b95f-72c6401d6e3a
A16: Deleted sheet count
A19: Last row used
A20: 31 | B20: 26
A25: Data blocks
A26: CB_Block_0
A27: 㜸〱敤㕣㙤㡣ㅣ㘵ㅤ摦㤹摢搹摢搹扢敢ㅤ扤昲㔲㕥㡦昷㤷㙢㤶㕥愱〲㘲㈹昷㐲摢㠳㤶ㅥ摤㙢㤱㈰㉥㜳扢捦摣㑤扢㌳㝢捣捣㕥㝢㠸㕡ㄴ㜹㔳㘳挰㐴〵㔱〹㌱㐴扥㤸攰〷〲㡡㌱㈶㐶㡤〱攳〷㌴㌱搱〴㠹搱てㅡ搳挴㉦㝣㈰挱摦敦㤹㤹摤搹摤摢戹㘳〱㍤捣㑤扢晦㍥昳扣㍦捦晦昵昹晦㥦㘹㑡㐹愵㔲敦攲攱扦㝣搲㑣㥣㕢㔸昶㝣㘱攷㈷慢㤵㡡㈸昹㔶搵昱昲攳慥㙢㉣敦户㍣扦〷ㄵ㌲㐵ぢ攵㥥㔶昴慣晢㐵戶戸㈴㕣て㤵戴㔴㉡㥢搵㔵㤴戳ㄳ晥㠶愲ㄷ㥤慤晡搳〰㠵挹㠹㠳㜳㐷搱㙢挱慦扡㘲摢挸㤱愰敤慥戱戱晣㔸㝥挷㜵㍢昳摢户㡤㑣搶㉡㝥捤ㄵ扢ㅣ㔱昳㕤愳戲㙤㘴愶㌶㔷戱㑡户㠹攵搹敡㌱攱散ㄲ㜳摢慦㤹㌳慥扤㝥散摡㥤㍢捤ㅢ㙥戸扥ㅦ㈳愷づ㑣㑥捣戸挲昴㍥㤸㉥㌵㑥昸摡㈹㔱戲戸㌲㈱㕣换㤹捦㑦㑥攰㙦㙣昶㜸扢㉥㕦㔸㄰挲攷挸挲ㄵ㑥㐹㜸㍡ㅡ昶搹攳㥥㔷戳ㄷ戹㜵扡扤〷ぢ㉤ㄹ㥥慦搹㤳愲㔲搱敤愸搷慣㝤㄰㍢㔷㌱㤶晢敤㠲㜰㍣换户㤶㉣㝦㌹㘳捦愲愳昲㠰㝤搸ㄳ㠷っ㘷㕥摣㙥搸㐲戳昷搶慣㜲㍡㜸㔲㍤㤷㐷㕤挴㈷㈶㔷㥦ㅦ昷散挹〵挳㤵㌳昲戸㉦〹㜵昷戸愵收扡ㄷ㜷敥㤷㔳㤷㈳戰捦㑢㍢搷㐳挹ㄱ挳慤搷ㅣ敤㕣㌳㕣㝣昳っ慥敥㕣㍦戶㐷捤㙤慥散摣㐶㙥㘵㜳㙤愵㉦愴㙥戹愳㔸㡣㥥㈱攸㈵挸ㄲ㄰㠱㝡㡥愰㡦愰ㅦ㐰㐹晦ㅢ㍣ㄲ㙦挸㈲戵㘸愸挵㌹戵㔸㔲㡢㘵戵㈸搴愲愹ㄶ攷搵攲㠲㕡戴搴攲㔱戵㜸っ㜵愲㈷摢摢慢㠶捦㑤摦㜸攱挴攳扦㝣晡收㐷㉦㜳㝥㜶捥㥦晡㝥摦扦〹㤵敥〸㈷㌵攵ㅡ挷㐱㙡つ㈲摥㤱摦捥㍦慢㌳〵㜸挲摣㘹㕥㘷㡥㡤㤵㜷㙥㌷慥㌱㌴㉥㉢〱昹㑤㠴㌲㠴扡晤收㥤㤶㔳慥ㅥ㤷戸㍢㜷挲昰㐴㘳攳㐶挳戲㠹㙡捤㈹㝢攷慣㕣㔸昰つ㕦㥣摤㕡搶攸愴慤㔹〱㙣㈵㍣㌹摥昹慤捤㡥ㄸ㤵㥡ㄸ㍦㘱〵挵攷戵ㄴ摢㌳㙥㜵慥㜳改ㅥ㔷摣㔷㉦㙤㥢搱㌸㐴摡㤲散扢㙤㤵㐱㔱㌰慦㤱挹㠵慡㈷ㅣ㌹扤㔱㝢挶㉡ㅤㄳ㙥㐱㔰㈰㡡戲㕣敡改㉣ち戹㝥昴愰㠳㠵㠲㕢换ㄷ挵㜳捤㕢㑥昸㘰㘶㔱挶㝣ㄷ㠵敢㉦捦ㅡ㜳ㄵ㜱㐶㔳㤵㘰㑣ㄴ㙣㙤捡摥㔳㉤搵扣挹慡攳扢搵㑡㜳挹㜸㜹挹㠰愴㈹ㅦ愸㤶㐵㍡㥤㤲㐲〱攲戶愷㐷㔱㔲㔷㜵收〵㠹㠸ㄸ㡡挹挸㘷㌵㤳㕤晥㄰㔶㠷㔵㔴〴㘹㔲扤㘴㤵捥㌸㕦㈹㘳ㄲ㌸㌰戶㈶㙡てづ㝡挵㉡摤搶㌱昷攱㔶㔶搵攱㜰昵户㉣〹挷摦㘷㌸攵㡡㜰ㄳ㜵㥦挲ㄹ改㠳〰摡㈹〸㠴㡥扢㐷㐵愷㥣㔰㤶戵攳㔶搹㕦挸㉣〸㙢㝥挱㐷ㅥ昴㘳㌶换慤㙤㝢昴搳㤰愵㙦㈶ㄸ〶挸攵㔲㤹㉤慣㤴挹攱㐹㘹㤴㑥〹扣摣㈴挸搹慥㠹㤷晢捤㍤㔶挵ㄷ㠱㔰ㅥ㌴㠱㤱㐰慢㐹昴つ㤰㐴㕤愳ㄴ㈸㡣㉤收㈴愸搴戰ㅣ㝦戹挱户㙤㕣ㄲ㄰搱㠶㉣㔸㜷戲㠰愲愰㔹ㅥ㈴昰ㅡ㠸愶㐵ㅡ㈴㔷㡥ㄱㄱ搹㈰㐱戳愳攷㘶㈲㘳晤〴ㄹ㠱晡㜱㈲㘴敤敤㥤㘵〴㠹扤㥤㐸搹愸㈳㍦㙥㐸戳㤵㉣昹㐰㥡㥤㡥㡤搳捦㈰㌸㤳攰㉣㠲慤〰捡摦㈰攱㈸攵㤰㙥㝥昴㜳昰慥㥦㑢㜰ㅥ〰攴㤳㑥㤹ㄳ㡡㉡摡㔰㙢戱㈳㔹㙦〰㜶戲㌴㡡〳㔱㐴换戸㙥㘷づ搸ㄲ搱愱搵戹㍥㜴㙤㕡敡搸换㍡搳㘶㝣㌹愴挸㠴慡昱戵慥㔲㌵扥ㄱ慣摡愵摥扡〰㑤昵ㄱ㠲ぢ〱〲挵㐲㘳㜷㙤搶㍣捤挹㡦㠴㐹ㄴㄸ㐲㕤㉡昷㤰㠸㘹晥㈷〸戸戶愳换㠶晤㑣㔳㜰搴晣挸摢捦摢㍡昳㜶㠸昴ㄶ㥤戹愱㜳攸㈹㝡㡦ㄶ昴㐵㘰㉦攵捦ㅤ昵换㈵㈸搶㉦㈵戸っ愰㐵扦昰攴晤㕥扤〴搲㈴戶㘳㤸摢㑣㡦㡢戴㜰㘷㤷ㄷ㠵搴㍥晤收慣攱捥ぢㅦ摥㡢改㈹搸挱㔵搷ㄵㄵㅣ㘸换㌲㠳㘷㤷㌳㥢㌳扤㍤㙥搵㘶晥㠶㝤散㝤㈴ㄴ㐳㍡慤昶愴㕡散攳〴㍢㌳收㙦㡡㔱づ昵敦㌵㥤㠵㐴慣㔱㌳㜹戱㕤昲搹㜲㐳㤲㜴㈱㐹慥挰戶敡㔷〲㐰㑡㈸㝦攸㈸㔱㐶㔹㙤㥢慣搶㙣慤搲扢㤷㜰㌲㘹昱ㅦ戶挹㤱扥挰㔹㍢〱摦㠱㌷㘰ㄷ㉣扢㉥㉣晡散ㄹ攱㤶攰㔷戰㉡㈲ㄷ戸㘴㈹㙡㌶㘴挵㐷㐴㔶昴昴戴㥤愵ㄳ㝣㙢㤲㑥㕡愴㐴㈲户㈷ㄶ㈶㥣挳ㅢ㐴㐵ㄷ㈴㠵㑡㠲㕢愸㉥㠱㐸㜹慣扢㈱㘲扡㄰㌱㜹㙣㥣㝥㌵挱㜶㠲㌱〰敤户㤰㌴㙢摤㜸〶挲㝡㤷攸捥㉥ㄶ㔳㔹愲㐱扡〷㕦敦㈸慣慥攵㌰㍢〹㍥〶搰㘲晥搰昹㤸㐰㠸ㄲ攵㌱㐲愴戵愴㥢㐷㉣㜱㥣㌴戰挹㐴㔰㘹戲收昹㔵㥢㔱愵〱㜳慡㝡㝢搵㥦戲扣㐵㐴愱㠶捤㌰㜱攷㠲㜰㐰㕤㉥㙣㥦㤶扣敡攲愲㈸敢㘶愱㕡㠳㘸㥢㥥㕡て㠷㜲慣て戶愴㍣㤷慢ち㥥敥捥挶攸㐲㤱㈷㘲昸㕡改㠹㕤㤳攷㥢㠷扥挱挶㡥捥㕡㝥㐵昴㤹〱搳㌱㥤㌵戱㡢㠸ㅡ㤴㝢捤搹〵㔷㠸愹〱㜳慦㙢㤵㉢㤶㈳㠸っ搸㤸っ搴敤ㄷ昳㠸㄰捣㔴ㄹ晦慢㍡〳收慣㙢㌸摥愲挱㘰攲昲收愶㌷ㄹㄲ搱捣〹换昱㌰㡣挴㈲搳㠳㘶㘱愱㝡ㅣ戱摡㥡敤散㌵ㄶ扤㜵㠱ㄵㄲ㝤昰㐸搴㈸慡愲慡㑡㔶捤㜶㡢ㅦㅥ挸㔳愹ㅤ昸愵〹㈴慥㔲ㅡ晤攵〹摡㥢㜶㝤ㄸ㥦愱㥤捥㌹昵㈳㜲㔴捦散㐹㤴挲攴㔴晤㝡戶戹〱㘰㝡敦攱改㐶㔴敥晤㐴慢㌵㍡昸ㄳ㐴扣愴㡡㝡っ㠴敥戹㑤〱愵㌰㡦㠴〳〶〴挲昹搶㑡㝤㌹㔳搶㈱昱㙤㙡㈴昷㈰㠸搴㙦敥㌷收㐴〵愱㘸摢昰㌷〵㉦戴㘲㙤愳攲㠵㘵㤳㔵摢㌶㐸㔹愴捡㐲挹㈰〱㡦搷晣敡〱换搱㑤〰㐹㝥㘱㤶㜱〲㔹挶〹㤹搵㙦ㅥ㘲㔴㔰愶搹㔷㜵摥㜰㉤㝦挱戶㑡㔹扥㌰㜲户㉥㐸ㄲ㍣㑥挱ㅢ㍤㤱挸ㄸ㘹㌱收て挳㘲昳昲挰㜶ㅥ㘲㤴㕢㐷散㠳㜰㔵㈵㠳㍦㑡㤷㝥㈵挸ㄷ改㈴搵㙦㐴㙦㥡扣ㄶ〱㠹㈳㥦㔳搱攵㡢㔳㥦㐷㑥攰㤶㈳搶ㄳ㐸〴づ挱㤸㡣愷㜷㍢㘳ㅥ㜶㉣ㅦ搸㈳挶昶㔸晥㤴〷㤴〳㈰㈹㑦户㘷㑢慣挶ㅡ㡤搶㤵挲〵敤㐵㑤㕡攲晣昶昲戸摡戸㘴㠵攲㐰愱挴昴挸㙡㤵愴㘲㔹㘱㡥敢㐹搳㈸㔲㙦㐷捡㐶㐹昲㥡㌶昶㥤㐲攴㝤攸㈵㐹㌳㈹㝤㤷㈴ㄴ挴㜸㐹ㅤ㔰㔱㜴搷㈷㤳㐷㉣㔸㐳ㄳ㈰㐷㌵ㄵ攴つ㠴搱挰㘹摣㌸㈹㡢㕣昸〶晥摥ㄴ㈶て搶晣愶ㄲ攳挴㜰㔸㌲㕥愹ㅣ㜴㘰㈴㤴っ户扣㑥㔸ㅡ㙢ぢㄴ㡣攴捥㙥㤵㝦戰扤㌱㐶っ搹㤰ㄱ㤱〴㌷㌰搸㄰捣ㄵぢ愶搲㌸ㅢ攰㔶搷戳戳㝣㍢㈰っ㐷㘲愰攰㤷愷挴㤲戴挲ㅡ㠶晣戰㙣㔰㍦㉣㑡㌹慡㥢攳㜳ㅥ㌴扡㑦㌹ㅥ愶㈴㠳敢收㈱㝡愵㜰㝦〱㘲㌷㑣捤㤴㝣㐴㜵敢ㅤ昰㘰戰㝥戰㠳ㅤ〹愲㈶㌴捥㈸㐱㌳〹㠴摢扣〸昲㑥㤷ㄸ㠵㈰㌵攵昳慦摤捡搳㑦昱㜹㘱㜷㉡㑡㠴㑣挴㐸㔷㠲昱〰攴挶㠳㤲攴愲攱㈸㔶ㅥ㐸㌶㈹戴晡愳㍣㕡ㄸ〳戴昸㕣ㅦㄷ㜸ㄸ挶ㅡ㈴摢㔴㜰挱捤户愰㑤㉢换㥢捣㘹愷㔴愹㤵㠵㔴挵㤱慣㤶ㅡ㜹㕤攰㑢摥晤ぢ戸㈹㘱㕦挲㑤㤹挶㐹㡡㑢㈶㤲扡㌷扢昵㥢搰㕣ち㌹昴ㄱ挸㌶挶ㅥㄳ扣㜲㌲ㄶ搶㜶㐵㠱收攱收挶摤〵㜹㙦づ㈲慤㉤㡢戲㙣㍦慥攲搵〳挸㤲摢㘲搵昶㔷昷㔷㘹戲挷戲昶㔹㐱搶扡挰ㄱ搶ㄹ〸扣㑣〶挶㐸㤷摣挱㑥㔲愷挲挰敥愹捦换搷搴愹摤愱昱愱㌰扣换㐳㔰ち扢ち㐶愲扤慤㌶㡣㙥㠵㠱㕦ㅡ摥晡捤〰ち㈳挰㌴㘸㔱㌳㌰㜰㈶㤰㕥摤挰㘱㉣㌲㈱㌸ㅡ㡦愳㌲㐴㌹っ㝦㍤㤰〶㙥攲㌹㝡戶ち㈵攴㙦㤱㜷挲愲㙢㠹愳㌶㑥㐰㔵昷㡣㤶捣ㄹ挳挷捤ㄷ㘷㙢㑢昶㜸戹㑣㜳ㄷ敥戹㜵㠱㔵摣摡〸捣搱㉤㉤昷戱攴㥡㘸摦㕤摣㔲㄰摥ㄳ摣㌱㤵摦㘷昸愵㠵㠲扦ㅣ摣搹敡㤶㈴戴㥦挲ㅤ戱攲攸戴㤹搳づ敦愰㉥㜱敦㜳挷㥣敡㜱㐷捥㑢昳㜸攱㡦㔶慣摥摢换㐹收㔲敦攲㡦㝣搴㤴昶㉡㝡㕣换戴搹㐱挳㍦挲㝥攴ㄳ㐸㠳ㄱ愴ㄳ攸〴戶㝢晤挲〰改㘴㑢ぢ㥤㐸㐱戰㐱㈸捥晣〷㐶㈸捡㑦㠰㔶ㄲ㑢㜰㈲挷㥥㍦て搶㔷㝥㡣ㅣ㈲ㅣ敦愱ㄸ搱㉥㐴㉡〱㜵㔲㤰㠷户㍢㜸ㄷ攴晦〷㑢ㄱ㌷慦挸㑥晦〵㘶㔶㕥㘹㐵搱昹㐴搱换敤㈸㘲ㅣ昶㍤㐵扣㌹晢㡤愳收㠷㝥慢昷㝦㜸搴扣ㄵㄸ收㈳慤㌱挴搴ㄸ㡢慦ㅢ〳㙡㥢㌱㜰㈹㡡愵㌱㜰ㅢ摢㌰㕣ㅦㄸ〳愱户攳〰㌲㔶㌷〶ㄸ挴㑢㌰昹㘲㌱搵㤸〳㠳㘷慤㌳㙣㝡挲昶攱㜶慤昰㄰戸㠷㝡昲㈶攱㝢㍡戳㍤㝢挶㜰つ㝢慢捣摦敢ち愸㉤㜷ㄶ搷戵㘵ㄳ戶㌸㝢挵ㄲ搹㘸〵慦㐴攴㑥摦昰㥣慣敤㤲㍡㌰ㄵ㍣㠱㥦㕥挹㉡㤹昷攱ㄳ㔱㜸㐲㐸㝤㘶换て昷晥攵晥㠷㜶昳㕡㕡㐸慢ㅡ攳挰摤挴收㘹㌹㈰㝡ㅢ扢ㄱ㜲㍡扦扥㌹㠰捦㤰慣挵㡡㤸㌰㕣㘹敦㜸扡ㅤ㈵〳挲㡢ㄱ㘶㐰㝣敢挱㤸挴〵㠷挰㤸捣户㌸㌶攵搷㑢搲ㄹ㤸㡦㑤㕣㝡敦愲昸愰搲㔱㘵㜵㘹㔷㙡㍦㠲搲㜹㡦ㄳ㘹戶〷㜹扥攴愳㈸㉦戶㙡戵㥤搴㙡搲㑣㔴㐶㔱㈳㤲㔲〸㌴㤰㐲攲㐷ㄶ㐶晥愵㤴㥡㐱㐲换〳㈴㠴搰㕡㘳戹㍣昹㙦〸〱㔱扦摤搷攵㤷㉡搸㐵㘰㌱昲扡㜷㝢㜶愵搵ㄹ愹㈶挶㘴攵改攳づ㈴攴㌱㠵ㄹっ搲捡摣㐳㐸㐴㡦㌶㠶搴㥡ㅤ㑦ㅣ㘴挰づ㈲㙣〱㘳㙢㌶扤㙡㌹晢ㄶ愷㠶㉢ㅥ搰㌳ㄹ愹㌰㥣捤捣挶搱㔳〶攳㠲慡戹㈰㡢㜰㌰㐸搶ㅢ昵㠵㐵搰㔹捥㔶㥣㍦ㄱ攵攳攷㐰㉣ㅦ㙤㜴㝤㝡㙢〹㜵㥣搳㡢〵昲〷晢敢晣〴挶挶愸攴ㄸ㐸搸㌵搵捡〶㜷挰ぢ㘸㈲敤㜹㐵㙦㈴㌹㤶愲㌰ㄸㅤ㜱㔶㑦扢晥㘷㤸㕡㜲搶㉣㙢㌳㕥摤愴晦㡦㈰㘳㔵晤慦㌰挸㈶㔱㜶㘷㤸攰㡢挶㐸挹慡挱ㄹ敥〸㝣搸〸搳挸㈳戰㉥㤳㡣㙤〷愹〲扥㑦つ㡡愵〴㠷㠷㉢摤㝡〷愲摥㤶戶㙤㕦㐷〱挸㈸㤰昶〳㠸愰㡥敤㌹改昶㜳㙣收㉥㘴㙦㌹㘰㤵摣慡㔷㌵晤㤱〲愲扢㈳晣挰捣㠴捤㌳慥㍣摦㉡搴㉥挶㑥昴摦㡤㌶〷づ㐲㘰摦㉥晣て㈸攸挸㄰挲摡㐲ㄶ晣搶㘸㈸ㄶ㐷愲㜲昰㑥㌳敦愸ㄹㄵ㝣㥥㝡㄰㑥㑤㥦㔹敢㐲搷〵慥攵搶㥢ㄸ摣㌹摣挵扡つ㡥ㅦ㔱挹㈳ち㈶㤷㜰昷㍤摣搶搶㍤㘸慥ㅢ慥捤㘳捤敥㥣㙢㌹敤晢㐰改摡㐶㘹愶ㄸ㡥挹慦㡥㜳晡㍤㠴〸昳搰㌹扡㜶㑦㉣㝢ㅢ〶㤹㠷㥦㙣搳攳㌵㕡㠱㥦㙣つ㔱敥㑦愳愹㜲㌳〱㝥㝡㌱㑣昰㐵愱㍢敦㐶㈶㥥挵戲㐸晦㐸愷㌲〶㐰㘷愲晥敥㑡㐴慤昰㘴㐱㉡捣㈹摦㐱㌹㜷㈹㔸㙤㤹㜹㌸㘹挸ㄳ〴搲扡〰㠸ㅥ㠵㈷〸㌹晥搳㘸㔰ㅦ㝦ㅥ戹㥤挷晦搶㡡攳㔳昷换昵挵晢ㅦ㡡㜴㠷㝥ㄴ挵晡㌱㠲ち㠱つ㌰ㄴ愹㤰㐱㑡㐵㡡㥡㑣㄰㐳㜸㘵㌷搲㜸㝥ㄷ晥晢收敥搷㕦攳昳捦摤㡡㤴㠳㈸㙡㕥〵攵愰㕣挵ㄳ昱㔵㉣㈲户昳㉡扥戶搲㉡㠶㈸㈲㌹ㄳ摤〵ㄸ攸㔱㐸㉢㜲㔵ㅥㄲ摣㔰晥ㄴ㠹㔰㈴㥡㘶㌱㐴挴捡戶㌵㈴搰㤶㍢㉦摢㉥㈱ㄱ戵ㅤ㡡戶㐷攳㡥㈴㝣挹㈳敤㈴摥㝣愴昷㈶ㄳ戸㕦㌳㠱㜶捣摡愱摦㜵㕤〸〹慣㡤㥦挶㜶ㄴ敤㤹㉥㘳晡捡㘳ㄱ㠶昶敤㡢㍥㤳㔲挳㈸ㄳ㈸㈴戰㑣㐹㔱摣㐸攵搱愸昲㡢㉦㌵㥣愴㈸挰〳㌲ち㉡㤳昲㘴攵㐷愲捡㍢昰〹㤶慣㤳攲㥤〱㍥㙦㐶㤵㐹愱戲昲挳㔱攵㝦散搸㕡慦ㅣㄱ㘴搰戳㐶㙡㐹戰㜹攵㈹㈰昶㌹㌶て搷㥡㐹㍤摡㘷〶搹ㄴ愱㌲㔸㕣㤱㥡戴ㅦ搷㍦㕣㝣㄰扤ㅦ㤷㤹㜰改〳搲㌶昸㝦ㄱ愶㜱挹㘹捡昰つ㝣敦扣㠴昰戲慢换㌷㌶捥㤸〷㕤㘴昴㥡搳ㅥ捥㔶攵㜵㐵㈲㌰ぢ搲挱晥慥攲㠶㑦㌰㈱ㅢ晢ㄱ㠵挵㔴摥ㅡ改㑥㡢挸㔰㑡㕡㜹㈸挲㙣敡㘴㠳㘶昴捦〲㌹㤰㤷㠰㑣攸㥦〳っ㐲㉦㕢㤸㌱㐴㐱㈰戹晣㈴ㄲ晡㠳〴㕦〰挸㈹攴㝡搲㐱收㡢〰㠳搱晦㑡㌱戲㈴晤㈶慡昲㐰㌴㔸㥣㡣昴㉦戱挱挳〰㍤㜰搸㉡㈱ㄱ收昴㐷㤰ㄳㅦ㤴ㄲ㐴づ晡ㄸぢㅥ㈷昸㌲㐰㑥攳㘴搷扣㙢㕣㔳㤷㉡散㉢㘸慡㜰㉢愴㐰晢㙡㤸攰㡢㜶ㄲ攰挶捥㌶㌳㡦挴搱㔷晣〸㙥㌶㝤慥㝦ぢ㍥扦㕦收愲㝢昰㥦㡦㘸搲挰㑦慢ㅦ敦慥㉦㌲㠱挶昹昰攷㘲戳摦㐷㍦㕣㔷挳搶㘴㡦㥦挰㉦慢㘶㤴〷昱敦㐹晣㤴晢㌰〲㐷愱捡捤挲摤㐲ㅡ㤰〵㡢㘱〱㜵㤷晥〴㠰㐲ㅣㄳ㑦晡㤳㝣㈳㙡搹扦晥昵㌰挱ㄷ㠵㜸㍤挹㐴㈵㙣ㅥつ㐸㕣换㠲㘳㉤〳ㄲ晦戲攰㘸㝣挰㙦㈲㔷㤱挸㐲愲㔹㍤ㄱ㘹㘹收㍥〵㌰搰㌳挸戹㔱摤愹㈷㤴搲扤攵㝢敦㝤㝢㌰㍤㜲㜶晡㤳㌷昷㍦昵收㙦摥㝡昲㡤㑦敤晡晢㍢捦㍣昳挶㕦㥦㝣敤㥤㔷攷㜶晤敡戹攷㝥㜱敢昷㕥㝢㙢戳昹慣晡搲摢晢㥦㝤㘰散搸〳昷㤹㠷慦摡晢挰㕤㐷敦ㄸ㥢㌹㙤戴愷愷户昷昲攱㕦㥦㜵挵搰挹晢㕥㔶㝥晥挷㌳ㅤ㐵㉥㤷〳ち㠰攸ㄹ攲戲攵㌴扥㡤〴愶挱ㄹ㝦愸搳攰㜲㑦攲愷㤴挳㡤㥡挰㑢ㄶ扥つ㑥㐰ㄶ㤴㥡ぢ晡晥〳㘹攷戲㍥
A28: Decisioneering:7.0.0.0
A29: CB_Block_7.0.0.0:1
A30: 㜸〱捤㔸㑤㙣ㅢ㐵ㄴ昶慥扤敢㕤摢㘹摤㌶㙤搳晦㠰㑡㘹㐹㜰攳愶㔱㝦㘸搵挶㜶晥搴㌴㐹㙢㌷㍤愱搵摡㍢ㅢ㙦戳扢㘳㘶搶㐹摣㡡ㅢ挷㕥㌹㜰㐴㜰㠱〳ㄲ㐲ㅣ㐰㐲攲㠰㐰攲挰摦ㄹづ〵㔵〸㠹㌳户ち摥㥢戵㔳摢㜱㘸ㅢ㠲搴㐹㍣㥥㤹㌷敦捤捣㥢昷扥昷挶ㄱ㈹ㄲ㠹晣つ〵扦戱挴戰㜱戸搸攰〱昱㌲㜹敡扡愴ㄲ㌸搴攷㤹㜱挶捣挶慣挳㠳㈸㑣㔰つ〷攸㕣㌱戸㜳㤷㘸挶ち㘱ㅣ㈶㈹㤱㠸愶改㌲搰㔱〸㝥搲慤㡥㡥㕣愹ㄸ㔴挵㝣㙥扥㝣〷愴ㄶ〳捡挸昰攰㘲挸㝢㌹㥢捤㘴㌳㘷捥㡤㘵㐶㠶〷昳㜵㌷愸㌳㜲搹㈷昵㠰㤹敥昰攰㐲扤散㍡㤵㙢愴㔱愲换挴扦㑣捡㈳愳㘵昳散昹散搹戱㌱晢挲㠵昳㈹㔸㌹㌲㥦捦㑤ㄳ户〶攲戶㐹愸ち㐲慦攷㜳ぢ㡣搸摢㈴㔲㐱㉤㘴ぢ愴攲愰扡〸㘱㡥扦㤴挹攷攰扦㑤㈵搰㍢㤷㤹㉦ㄶ㠹捦㥤挰㔹㜱㠲〶㥥㑥昷收㉢攵㐵搳慤ㄳ搵ㄳ㍢搲扣㐵㤳捤㤹ㅥ改昳㙥㜱㜲搳昴㤷〸昶ㄴ㙦慡敥㔸㌱戸挶攸愹㕥ぢ㌵㔵㤴〱㙤攵慢㈶ぢ㠴㐸㕣攰㜴慦搹㘲愵㑣摢㔶〴㡦ㄸ㐵敤㐸挹愶愱㠸㌵㜱㤷㜱慣㌴愸㔴ㅤ慡㍤㙤㥣㠳㠲㜵㌰㉢挵晥〲㜳㙢㘷㑣挲㑣搹㌰㘵愳㉣ㅢㄵ搹戰㘴㠳挸㠶㉤ㅢ㑢戲㔱㤵つ㐷㌶敥挸挶㌲捣㘹ㄵ㉤ㅥ㤷㥢攵㡢㑢㉡㝤㔸晡㝤晡挳㠱ㅦ搹㥢敦㝦㜲㈹㠵戲慥挳搹㌲㜳㈴搸ㅥ㌳㔰昰㐸㑦慦捡ㄴ捣㔶扣昰㈶ち㠴㔷㜴扣愶ㄹ摦㈲㙢㉡戴攰晡㔲㕥㥥晡〱㔹ぢち㘶㘰挶扤〵㤳ㄱ㍦搰㘱搲㤰攰ち㕢挸搹㈷挶㕡摣㠹㘶て㈴愴㐵戳㑤㑡㔲っ㠴㤲㈴㜰扢㘸㉣慣㌵戵㤷㈳㑦㥢扣ㅡ㤸㘵㤷ㅣ敦扡㜱㔴ㅢㄸ搹慤挰㜱㜹〶㐴㑥㌱㕡慦愱㐲户㑢㡥戰㘳戴ぢ戵て㉡〱㍢昸つぢ㕣搵㜷挰㔷㐲㐷愲㡥㐴㠴㈴昸㠲搲愲愵㜶㐳㘷㉥㥦㉢㔰捦㜴晣敤戹摢搴ㅥ㤰㜹愳㘹挳〵㘶慥㠲㍦㍥㤶㝣㈶㌳㠲㝦㑦㠶㈳㐰㈳㝢捣㍥㘷㘷戳搶搸㠸㌹㙡㉡攸〰捦敡㑦晤挰㤳昲㙥㍢扥㐵㔷㠵㠳敤昶挰㝢㠴搳㤴ㅡ㌵㈲㠶㔲㜶挹㘴㑢〴㥣㤶捤ㄴ晡敤㍣㘵㡣戸㘶㐰㉣㌱㠰攰扣扦㜳㤰㑦㌲敡攱昸攱㥣挹挹㘳攷ㅤ戲挳㠵㜲戴敥㕢晣㔰㙦㘲㌱〰搱〷扢㘹㡦㠵㙣㘰㉢〲愰ㄱ㉥㜶㝡戴㥢㑤搸晥昸㥡ㄳ㤲㡦㜴㤱〱搲㘸㜹㜳敡㈴㈳㙦慣㔳㌷散㘸ㅣ㈲搴ち㐱晡㠶㔳㠶愴㜰㕦〰㐰㤴ㄳ㕦㙣㙦挸㕢㜰㉡换㠴ㄵ〹挶㌷㘲㠹愳敥㐵ㄲ〱㜷慣㄰㍥㌴㡦慡〷㑣戵㕥㙣ㅦ戵㈷搶〲〲捥㙣挱㝥㈱搲〴㡤ㄲ㍡搲扥㡥㈹攱㥡㐰㌸搰㌱㍣㐹㉢㜵㡥㑥换愸摢㐹ㄹ户㔶㑣㔸搳扡㑥㉤ㄲ㡢挹搱㐸㉣ㄲ挳〲ㄱ㌴ㅡ〵㑦ㅥ改昲㔳ㄱ㌰㔰㌶㙦㐷收㌶换㐱㘸ㅥ㝤㉡愶㑥昳㐲扥㕥㠸戱ㅥ晡愵㠱㑥㕦挹摣〴敤㠱㤶㕣㠲㡥㈴㜷〳㑡摢㐶ㅦ㕢つ㉥搲ㄳ㑥挳ㄳ戵改っ敤ㄶ㘷㥦摣晣㈸㐲散扡㘵晣扦㤳㘵㜹㑦昳昴ㄳ㉢〰搹搳愶㙦戹㠴晤扢扥㜰㐷㍡㝡戶扥ㄷ慢㝤㔰㈵㈲捡ㅦ〰㙥㥢㙡ㄲ㜳㈴㘹㑤㙡㈸慢㡥ㄵ㔴搵㉡㜱㤶慡〱㡣㐱㙡愵㘹愸收㠳捤捦户㠰昴ㅦ㘰㤲愵て㘰㜵〰慡㐴㈲ㄱ挲愷㥡搰て㠹㝥㈴㠶挰摡㙢㤳敢㘱〰攳㕢㘲㤶㥡搶愴㔹㠱㤴㉣摥㑣挸戴㍣昵㙡㄰㥣㔸ㅡ㘷收挱㌶挱收㔷ㅣ㡢㌰つ〷㡡㤰昸挵㈰㈱攳慡昰㙣づ㔱㈷ㅡ㔱㤴愴搶㙢慤㤹㤶慣攳㑤つ戶㈷㤶㌳ㅢ攴晦㜹攳晣ㄵ㑣ㅣㄳ〹㡣㍥晡㘱慣㡥㐰愵愰㈶㥦搹ㅢ㜶〲搳㍥慦㔸愵慢搳愰㑡挲挳㤴㠷攷㤹ㄳ散摦㌸っ㔱搴昴づ㠸昱㈹㐶〰〰㔹〹㜰㐰㥣ㄱ㌹づ昶愴〸愶㠳挲ㄸ摢摣㜰挸㕥㜴挸㉡㠲昷戱㡤㈴挸搹昲㜵ㅥ㔰ㄱ昴㡦㙥愴ㄷ攸ㅣつちづ慦戹㘶攳㜸て㜲㐸戹㕤㈵㍥㘰ㄷ〳〸㝢搲㈴㕡慢ㄱ慢挷ㅥ㡢戴捥㉡㘴愶昰㍣愰ㅦ摣㔴㔸㈴〱㝣㤲㈶愹戲〴㘵㙢㡥㈷愱㑢㐴敥昵㝦㌴昵攰敥㕢㔷㔴㠰㔳〹ㅣ〴㕣㐴㐱㘷摣ち㐰㘲㝡搲搷ㄱ㤶昷㘲昲㝤ㅤ㥥㉢㑥捤㈵㌹㤳㠱㘱㔳挶㜵慦搵っつ慦㉤つづ扤攵㜹㔰㌶㐴㤹㌰扥㘴㌶挷搷戶㡤ぢㅢ㐴㘳㐶㑣㤳晡扢〲㠱㌸㌷愲搳ㄶ敦㑡昹ㄵ㌰昱ㄹ㌷㠲搸ㄷ㕦挱㥣摡㌰㈰㐷㠵ㅥㄶ㐹㜹〰愲㝡敥て愱㌵收攳㈳㐹㜰㈵㤶㝤扡敡㡢㥤㉢ㅣ㜳ㅤ〱愶昱㌸ㅥ㈳㠱愲戰㡣戵捣㈶愲㈰㝡て昵搲㔵㤸㤲慥扦攲㘶㉣〸て捤㘷㕢ち㥦㙤㈵㐶挴摢㑣ㄳㅤ㔰㘱㥦㜷㥢戲攵㌲愵换昸㔰搸㈱㝡扣㑡㐸㠰敦愸愴ㄷ㍥〶戱つ戶ㅦ㡤㜶扣㤵㥡㝡㐷㈲㈶挴㈲㔹㔶㕦㠰㔶㜴㤲㔵㐴㑦晡〵捥㡦㙦慣晢扦㑤㥣㝥㌴㌲㤶晢捣㘰㕦㕦㍤攲㕦㤴㝥㙥ㄲ扥㍡㜳愲㝦搷搸晥戹晢て摦㝢晢㥢㐷搷㍥㔶㌰㠰㍣㔵昰㑥挳挴㥤昶㍡㜶㤵㥣挰㈵㐹㍢㌴つ㙣㙢㌶愰ㄱ㈴㔶㔶摣㉥㔵攱搴㠵㍥㝢㡡㌹㤶敢昸〴㑤〷㔲㔶㝣㜳捥㤲㈵㐸愲ㄶ㈸扥㙦愹摦㘷㤷㤸改㜳㡣㌵㝥愵戱扢愳㈷扣㐵戱㜳㡥捦㘱ㄹ㠱㤷搸摥㘹㈳㥣挳捤搵㍤㝦捡慣昱攷挱㥤挴敦ㅤ愰ㅥ㈸㈱㜸挹㤲㉣㑢㥡慣㙤搱㈳㈲敡㑢㈰㉡摤收㠱ㄷ〷ㄷㄷ㐶㈰捤㤲〵戰挹㘷㜰愹㄰捦㄰攸㥥㍥愷㐲㌳㑦㠹ㅦㄱ㥡挹㙥戴㔷捣㕥㑦晡㐴づ㜳〲㜸㈴㑣㈹㠴㡦扣摣㙣㘰㈷㡤攱ㄹ愳戵㝡ㄲ慡㕤昹㥣ㄱ㥡㙦换ぢ搴㔳㌰扣〳㠶摢㌲扢㌴㐶㜳攴搱㕦挱ち㥦㑢㤲㔸〱㝢挳㔰戵㑡ㅡ㔷㐲户搵㕦㠵慡㉦㉡攱㝣昴㐳㌵㠳晤㜱搷ㅤ㙣㜹ㄲ搷㜱㐸㍤つ搵挰㠲〹晥㥣㥤㜵㔶ㄸ戹㐹㤶敡慥㘹搱捣㥡换搷愴ㅦ㥡ㅥ㘰换戳昵㠱㠱㥦愶㍦扤㤷㝤㌷㝢㘸昶㑢改晢㈶愱晢〷㠵㜴㙢㌷ち㙥攰戵㕥摥扦㈱㙦ㅤ敡㝥㈴㑣㐰搲摦挰攳㐶㈱㘱㔲㠴㑤挷攴㡢㕢㤳搵㐲㘰扣ㄵ攵㍢搸昵㝦㤰㠳搷搷〹愰挷㘰㐴ㅦ㐵搱㔸㜵㠳㈸收㝣㤳㜸㡥慥摣㌴㤹㐴挸㉣扤昳昹搵㐷愳慦㡦㈷晦〱㘰晢㙥ㄴ
A31: Decisioneering:7.0.0.0

Sheet Plan4
A1: Bloco | B1: Freqüência
A2: -0.76784218 | B2: 1
A3: -0.56334354 | B3: 23
A4: -0.3588449 | B4: 119
A5: -0.15434625 | B5: 222
A6: 0.05015239 | B6: 178
A7: 0.25465103 | B7: 139
A8: 0.45914968 | B8: 92
A9: 0.66364832 | B9: 65
A10: 0.86814696 | B10: 46
A11: 1.0726456 | B11: 34
A12: 1.2771442 | B12: 29
A13: 1.4816429 | B13: 13
... A32: 5.3671171 | B32: 0
A33: Mais | B33: 1

Sheet Plan1
A2: Investimento total | B2: =B3*G4 -> 50000000 | D2: Taxa_desconto | E2: 0.15 | F2: dividendo | G2: 0.05
A3: Total MW | B3: 10 | D3: Taxa Liv Risco | E3: 0.07 | F3: Fator | G3: 0.2
A4: Produção anual MWh | B4: =B3*24*365*G3 -> 17520 | D4: sigma_Preço | E4: 0.02 | F4: Invest MW | G4: 5000000
A5: Capital próprio | B5: =B2*(1-B8) -> 50000000 | D5: tx_cresc_Normal | E5: 0.05 | F5: Custo Manutenção | G5: 0.01
A6: Custo Manutenção por MW | B6: =B7/B3 -> 50000 | D6: T(ano) | E6: 1 | F6: miManutenção | G6: 0.05
A7: Custos totais de manutenção | B7: =B2*G5 -> 500000 | D7: Num passos | E7: 4 | F7: Perda de potência | G7: -0.0075
A8: Percentual financiável | B8: 0 | D8: DeltaT | E8: =E6/E7 -> 0.25 | F8: Varia irradiação | G8: 0.05
A9: Preço mercado livre | B9: 500
A10: Faturamento | B10: =B4*B9 -> 8760000
A11: Outros custos | B11: 0.005
A12: VP0 | B12: =VPOi!B9 -> 68820591
A13: VPL | B13: =B12-B5 -> 18820591 | D13: Cenário com CO2 | F13: 0
A14: Média_Ret_VP | B14: =AVERAGE(J17:J1016) -> 0.13228432 | E14: Preço CO2 ini | F14: Preço CO2 fin | G14: Cresce por ano
A15: DesvPadRet | B15: =STDEV(J17:J1016) -> 0.12223276 | D15: CO2 | E15: =IF(F13=1,50,0) -> 0 | F15: =IF(F13=1,150,0) -> 0 | G15: =IF(F13=1,2.5,0) -> 0
D16: CO2-e/kWh | E16: =IF(F13=1,0.41,0) -> 0 | F16: ton/MWh | I16: Simulação | J16: Retorno | K16: VPL
A17: VP0/I | B17: =B12/B5 -> 1.3764118 | I17: 1 | J17: =LN('VPI1'!A6/VPOi!$B$9) -> 0.018205555 | K17: =('VPI1'!A6/(1+Plan1!$E$2))/1000000 -> 60.943464
D18: upper | E18: =EXP(B15*E8^0.5) -> 1.0630226 | I18: 2 | J18: =LN('VPI1'!A7/VPOi!$B$9) -> 0.022668498 | K18: =('VPI1'!A7/(1+Plan1!$E$2))/1000000 -> 61.216059
A19: Decisão | D19: down | E19: =1/E18 -> 0.94071375 | I19: 3 | J19: =LN('VPI1'!A8/VPOi!$B$9) -> 0.15718603 | K19: =('VPI1'!A8/(1+Plan1!$E$2))/1000000 -> 70.030235
A20: Modelo Binomial | B20: =IF(D31>B13,"Espera","Investe") -> Espera | D20: p | E20: =(EXP((E3-G2)*E8)-E19)/(E18-E19) -> 0.52570814 | I20: 4 | J20: =LN('VPI1'!A9/VPOi!$B$9) -> 0.068447502 | K20: =('VPI1'!A9/(1+Plan1!$E$2))/1000000 -> 64.083605
A21: Black&Scholes | B21: =IF('Black&Scholes'!D16>B13,"Espera","Investe") -> Espera | I21: 5 | J21: =LN('VPI1'!A10/VPOi!$B$9) -> 0.1454575 | K21: =('VPI1'!A10/(1+Plan1!$E$2))/1000000 -> 69.213681
D22: Valor Presente dos Fluxos em cada nó da árvore binomial | I22: 6 | J22: =LN('VPI1'!A11/VPOi!$B$9) -> 0.24382655 | K22: =('VPI1'!A11/(1+Plan1!$E$2))/1000000 -> 76.368294
A23: Valor com Opção | D23: 0 | E23: 1 | F23: 2 | G23: 3 | H23: 4 | I23: 7 | J23: =LN('VPI1'!A12/VPOi!$B$9) -> -0.11135204 | K23: =('VPI1'!A12/(1+Plan1!$E$2))/1000000 -> 53.537857
A24: =A20 -> Modelo Binomial | B24: =D31 -> 18844481 | D24: =B12 -> 68820591 | E24: =D24*$E$18 -> 73157845 | F24: =E24*$E$18 -> 77768444 | G24: =F24*$E$18 -> 82669616 | H24: =G24*$E$18 -> 87879671 | I24: 8 | J24: =LN('VPI1'!A13/VPOi!$B$9) -> 0.10038842 | K24: =('VPI1'!A13/(1+Plan1!$E$2))/1000000 -> 66.163534
A25: =A21 -> Black&Scholes | B25: ='Black&Scholes'!D16 -> 18850016 | E25: =D24*$E$19 -> 64740477 | F25: =E24*$E$19 -> 68820591 | G25: =F24*$E$19 -> 73157845 | H25: =G24*$E$19 -> 77768444 | I25: 9 | J25: =LN('VPI1'!A14/VPOi!$B$9) -> 0.19740522 | K25: =('VPI1'!A14/(1+Plan1!$E$2))/1000000 -> 72.904201
A26: Valor da Opção | F26: =E25*$E$19 -> 60902257 | G26: =F25*$E$19 -> 64740477 | H26: =G25*$E$19 -> 68820591 | I26: 10 | J26: =LN('VPI1'!A15/VPOi!$B$9) -> 0.040358745 | K26: =('VPI1'!A15/(1+Plan1!$E$2))/1000000 -> 62.308621
A27: =A21 -> Black&Scholes | B27: ='Black&Scholes'!D16-Plan1!B13 -> 29424.974 | G27: =F26*$E$19 -> 57291591 | H27: =G26*$E$19 -> 60902257 | I27: 11 | J27: =LN('VPI1'!A16/VPOi!$B$9) -> -0.05270716 | K27: =('VPI1'!A16/(1+Plan1!$E$2))/1000000 -> 56.771469
A28: =A24 -> Modelo Binomial | B28: =D31-B13 -> 23889.154 | H28: =G27*E19 -> 53894988 | I28: 12 | J28: =LN('VPI1'!A17/VPOi!$B$9) -> 0.055772336 | K28: =('VPI1'!A17/(1+Plan1!$E$2))/1000000 -> 63.27646
I29: 13 | J29: =LN('VPI1'!A18/VPOi!$B$9) -> 0.31952593 | K29: =('VPI1'!A18/(1+Plan1!$E$2))/1000000 -> 82.373763
B30: =AVERAGE('VPI1'!A6:A1005) -> 79143680 | D30: Valor presente líquido com a opção de espera | I30: 14 | J30: =LN('VPI1'!A19/VPOi!$B$9) -> 0.17878353 | K30: =('VPI1'!A19/(1+Plan1!$E$2))/1000000 -> 71.559164
D31: =(E31*$E$20+E32*(1-$E$20))*EXP(-$E$3*$E$8) -> 18844481 | E31: =(F31*$E$20+F32*(1-$E$20))*EXP(-$E$3*$E$8) -> 23022512 | F31: =(G31*$E$20+G32*(1-$E$20))*EXP(-$E$3*$E$8) -> 27568064 | G31: =(H31*$E$20+H32*(1-$E$20))*EXP(-$E$3*$E$8) -> 32510065 | H31: =MAX(H24-$B$5,0) -> 37879671 | I31: 15 | J31: =LN('VPI1'!A20/VPOi!$B$9) -> 0.22209816 | K31: =('VPI1'!A20/(1+Plan1!$E$2))/1000000 -> 74.726831
E32: =(F32*$E$20+F33*(1-$E$20))*EXP(-$E$3*$E$8) -> 14914950 | F32: =(G32*$E$20+G33*(1-$E$20))*EXP(-$E$3*$E$8) -> 18841134 | G32: =(H32*$E$20+H33*(1-$E$20))*EXP(-$E$3*$E$8) -> 23116452 | H32: =MAX(H25-$B$5,0) -> 27768444 | I32: 16 | J32: =LN('VPI1'!A21/VPOi!$B$9) -> 0.061196777 | K32: =('VPI1'!A21/(1+Plan1!$E$2))/1000000 -> 63.620633
F33: =(G33*$E$20+G34*(1-$E$20))*EXP(-$E$3*$E$8) -> 11118304 | G33: =(H33*$E$20+H34*(1-$E$20))*EXP(-$E$3*$E$8) -> 14803646 | H33: =MAX(H26-$B$5,0) -> 18820591 | I33: 17 | J33: =LN('VPI1'!A22/VPOi!$B$9) -> 0.043630502 | K33: =('VPI1'!A22/(1+Plan1!$E$2))/1000000 -> 62.512814
G34: =(H34*$E$20+H35*(1-$E$20))*EXP(-$E$3*$E$8) -> 7447291.7 | H34: =MAX(H27-$B$5,0) -> 10902257 | I34: 18 | J34: =LN('VPI1'!A23/VPOi!$B$9) -> 0.34191113 | K34: =('VPI1'!A23/(1+Plan1!$E$2))/1000000 -> 84.23851
G35: =(H35*$E$20+H40*(1-$E$20))*EXP(-$E$3*$E$8) -> 2012105 | H35: =MAX(H28-$B$5,0) -> 3894987.7 | I35: 19 | J35: =LN('VPI1'!A24/VPOi!$B$9) -> 0.36525699 | K35: =('VPI1'!A24/(1+Plan1!$E$2))/1000000 -> 86.228266
I36: 20 | J36: =LN('VPI1'!A25/VPOi!$B$9) -> 0.20063106 | K36: =('VPI1'!A25/(1+Plan1!$E$2))/1000000 -> 73.139758
I37: 21 | J37: =LN('VPI1'!A26/VPOi!$B$9) -> 0.012415539 | K37: =('VPI1'!A26/(1+Plan1!$E$2))/1000000 -> 60.591619
I38: 22 | J38: =LN('VPI1'!A27/VPOi!$B$9) -> 0.22931237 | K38: =('VPI1'!A27/(1+Plan1!$E$2))/1000000 -> 75.267876
I39: 23 | J39: =LN('VPI1'!A28/VPOi!$B$9) -> 0.074469605 | K39: =('VPI1'!A28/(1+Plan1!$E$2))/1000000 -> 64.470687
I40: 24 | J40: =LN('VPI1'!A29/VPOi!$B$9) -> 0.1758467 | K40: =('VPI1'!A29/(1+Plan1!$E$2))/1000000 -> 71.349316
I41: 25 | J41: =LN('VPI1'!A30/VPOi!$B$9) -> 0.27882109 | K41: =('VPI1'!A30/(1+Plan1!$E$2))/1000000 -> 79.088078
...

Sheet VPI1
A1: Crédito CO2 | B1: =Plan1!$E$15 -> 0 | C1: =B1+Plan1!$G$15 -> 0 | D1: =C1+Plan1!$G$15 -> 0 | E1: =D1+Plan1!$G$15 -> 0 | F1: =E1+Plan1!$G$15 -> 0 | G1: =F1+Plan1!$G$15 -> 0 | H1: =G1+Plan1!$G$15 -> 0 | I1: =H1+Plan1!$G$15 -> 0 | J1: =I1+Plan1!$G$15 -> 0 | ... V1: =U1+Plan1!$G$15 -> 0
A2: Manutenção | B2: =Plan1!B7 -> 500000 | C2: =B2*(1+Plan1!$G$6) -> 525000 | D2: =C2*(1+Plan1!$G$6) -> 551250 | E2: =D2*(1+Plan1!$G$6) -> 578812.5 | F2: =E2*(1+Plan1!$G$6) -> 607753.12 | G2: =F2*(1+Plan1!$G$6) -> 638140.78 | H2: =G2*(1+Plan1!$G$6) -> 670047.82 | I2: =H2*(1+Plan1!$G$6) -> 703550.21 | J2: =I2*(1+Plan1!$G$6) -> 738727.72 | ... V2: =U2*(1+Plan1!$G$6) -> 1326648.9
A3: PMT = JUROS + AMORTIZAÇÂO | C3: =BNDES!$H6 -> 0 | D3: =BNDES!$H7 -> 0 | E3: =BNDES!$H8 -> 0 | F3: =BNDES!$H9 -> 0 | G3: =BNDES!$H10 -> 0 | H3: =BNDES!$H11 -> 0 | I3: =BNDES!$H12 -> 0 | J3: =BNDES!$H13 -> 0 | K3: =BNDES!$H14 -> 0 | L3: =BNDES!$H15 -> 0 | M3: =BNDES!$H16 -> 0 | N3: =BNDES!$H17 -> 0 | O3: =BNDES!$H18 -> 0 | P3: =BNDES!$H19 -> 0 | Q3: =BNDES!$H20 -> 0 | R3: =BNDES!$H21 -> 0 | S3: =BNDES!$H22 -> 0 | T3: =BNDES!$H23 -> 0 | U3: =BNDES!$H24 -> 0 | V3: =BNDES!$H25 -> 0
A4: Fator para VP | C4: =1/(1+Plan1!$E$2)^(C5-1) -> 1 | D4: =1/(1+Plan1!$E$2)^(D5-1) -> 0.86956522 | E4: =1/(1+Plan1!$E$2)^(E5-1) -> 0.75614367 | F4: =1/(1+Plan1!$E$2)^(F5-1) -> 0.65751623 | G4: =1/(1+Plan1!$E$2)^(G5-1) -> 0.57175325 | H4: =1/(1+Plan1!$E$2)^(H5-1) -> 0.49717674 | I4: =1/(1+Plan1!$E$2)^(I5-1) -> 0.4323276 | J4: =1/(1+Plan1!$E$2)^(J5-1) -> 0.37593704 | ... V4: =1/(1+Plan1!$E$2)^(V5-1) -> 0.070265321
A5: Valor Presente | C5: 1 | D5: 2 | E5: 3 | F5: 4 | G5: 5 | H5: 6 | I5: 7 | J5: 8 | K5: 9 | L5: 10 | M5: 11 | N5: 12 | O5: 13 | P5: 14 | Q5: 15 | R5: 16 | S5: 17 | T5: 18 | U5: 19 | V5: 20
A6: =SUM(C6:W6) -> 70084983 | B6: 1 | C6: =((Produção!C4*PreçoLivre!C6*(1-Plan1!$B$11)+C$1*Plan1!$E$16)-C$2-C$3)*C$4 -> 9199833.9 | D6: =((Produção!D4*PreçoLivre!D6*(1-Plan1!$B$11)+D$1*Plan1!$E$16)-D$2-D$3)*D$4 -> 7234073.6 | E6: =((Produção!E4*PreçoLivre!E6*(1-Plan1!$B$11)+E$1*Plan1!$E$16)-E$2-E$3)*E$4 -> 6409452.5 | F6: =((Produção!F4*PreçoLivre!F6*(1-Plan1!$B$11)+F$1*Plan1!$E$16)-F$2-F$3)*F$4 -> 5572823.7 | G6: =((Produção!G4*PreçoLivre!G6*(1-Plan1!$B$11)+G$1*Plan1!$E$16)-G$2-G$3)*G$4 -> 4623067.6 | H6: =((Produção!H4*PreçoLivre!H6*(1-Plan1!$B$11)+H$1*Plan1!$E$16)-H$2-H$3)*H$4 -> 4252541.2 | I6: =((Produção!I4*PreçoLivre!I6*(1-Plan1!$B$11)+I$1*Plan1!$E$16)-I$2-I$3)*I$4 -> 3784430.4 | J6: =((Produção!J4*PreçoLivre!J6*(1-Plan1!$B$11)+J$1*Plan1!$E$16)-J$2-J$3)*J$4 -> 3604928 | ... V6: =((Produção!V4*PreçoLivre!V6*(1-Plan1!$B$11)+V$1*Plan1!$E$16)-V$2-V$3)*V$4 -> 1132531.4
A7: =SUM(C7:W7) -> 70398467 | B7: 2 | C7: =((Produção!C5*PreçoLivre!C7*(1-Plan1!$B$11)+C$1*Plan1!$E$16)-C$2-C$3)*C$4 -> 8363983 | D7: =((Produção!D5*PreçoLivre!D7*(1-Plan1!$B$11)+D$1*Plan1!$E$16)-D$2-D$3)*D$4 -> 7416047.5 | E7: =((Produção!E5*PreçoLivre!E7*(1-Plan1!$B$11)+E$1*Plan1!$E$16)-E$2-E$3)*E$4 -> 6169363.5 | F7: =((Produção!F5*PreçoLivre!F7*(1-Plan1!$B$11)+F$1*Plan1!$E$16)-F$2-F$3)*F$4 -> 5344505.8 | G7: =((Produção!G5*PreçoLivre!G7*(1-Plan1!$B$11)+G$1*Plan1!$E$16)-G$2-G$3)*G$4 -> 5487104.4 | H7: =((Produção!H5*PreçoLivre!H7*(1-Plan1!$B$11)+H$1*Plan1!$E$16)-H$2-H$3)*H$4 -> 5021104.4 | I7: =((Produção!I5*PreçoLivre!I7*(1-Plan1!$B$11)+I$1*Plan1!$E$16)-I$2-I$3)*I$4 -> 4215055.3 | J7: =((Produção!J5*PreçoLivre!J7*(1-Plan1!$B$11)+J$1*Plan1!$E$16)-J$2-J$3)*J$4 -> 3650320 | ... V7: =((Produção!V5*PreçoLivre!V7*(1-Plan1!$B$11)+V$1*Plan1!$E$16)-V$2-V$3)*V$4 -> 1058062.5
A8: =SUM(C8:W8) -> 80534770 | B8: 3 | C8: =((Produção!C6*PreçoLivre!C8*(1-Plan1!$B$11)+C$1*Plan1!$E$16)-C$2-C$3)*C$4 -> 8661665.7 | D8: =((Produção!D6*PreçoLivre!D8*(1-Plan1!$B$11)+D$1*Plan1!$E$16)-D$2-D$3)*D$4 -> 7553561.9 | E8: =((Produção!E6*PreçoLivre!E8*(1-Plan1!$B$11)+E$1*Plan1!$E$16)-E$2-E$3)*E$4 -> 6322462.5 | F8: =((Produção!F6*PreçoLivre!F8*(1-Plan1!$B$11)+F$1*Plan1!$E$16)-F$2-F$3)*F$4 -> 5582998.5 | G8: =((Produção!G6*PreçoLivre!G8*(1-Plan1!$B$11)+G$1*Plan1!$E$16)-G$2-G$3)*G$4 -> 5380071.8 | H8: =((Produção!H6*PreçoLivre!H8*(1-Plan1!$B$11)+H$1*Plan1!$E$16)-H$2-H$3)*H$4 -> 5313459.7 | I8: =((Produção!I6*PreçoLivre!I8*(1-Plan1!$B$11)+I$1*Plan1!$E$16)-I$2-I$3)*I$4 -> 4951446.7 | J8: =((Produção!J6*PreçoLivre!J8*(1-Plan1!$B$11)+J$1*Plan1!$E$16)-J$2-J$3)*J$4 -> 4359391.2 | ... V8: =((Produção!V6*PreçoLivre!V8*(1-Plan1!$B$11)+V$1*Plan1!$E$16)-V$2-V$3)*V$4 -> 1501371.9
A9: =SUM(C9:W9) -> 73696145 | B9: 4 | C9: =((Produção!C7*PreçoLivre!C9*(1-Plan1!$B$11)+C$1*Plan1!$E$16)-C$2-C$3)*C$4 -> 8862652.2 | D9: =((Produção!D7*PreçoLivre!D9*(1-Plan1!$B$11)+D$1*Plan1!$E$16)-D$2-D$3)*D$4 -> 7483442.9 | E9: =((Produção!E7*PreçoLivre!E9*(1-Plan1!$B$11)+E$1*Plan1!$E$16)-E$2-E$3)*E$4 -> 6437663.4 | F9: =((Produção!F7*PreçoLivre!F9*(1-Plan1!$B$11)+F$1*Plan1!$E$16)-F$2-F$3)*F$4 -> 5385289.8 | G9: =((Produção!G7*PreçoLivre!G9*(1-Plan1!$B$11)+G$1*Plan1!$E$16)-G$2-G$3)*G$4 -> 5265244.3 | H9: =((Produção!H7*PreçoLivre!H9*(1-Plan1!$B$11)+H$1*Plan1!$E$16)-H$2-H$3)*H$4 -> 4905631.5 | I9: =((Produção!I7*PreçoLivre!I9*(1-Plan1!$B$11)+I$1*Plan1!$E$16)-I$2-I$3)*I$4 -> 4445905.2 | J9: =((Produção!J7*PreçoLivre!J9*(1-Plan1!$B$11)+J$1*Plan1!$E$16)-J$2-J$3)*J$4 -> 3864130.4 | ... V9: =((Produção!V7*PreçoLivre!V9*(1-Plan1!$B$11)+V$1*Plan1!$E$16)-V$2-V$3)*V$4 -> 1268960.9
A10: =SUM(C10:W10) -> 79595734 | B10: 5 | C10: =((Produção!C8*PreçoLivre!C10*(1-Plan1!$B$11)+C$1*Plan1!$E$16)-C$2-C$3)*C$4 -> 9352001.2 | D10: =((Produção!D8*PreçoLivre!D10*(1-Plan1!$B$11)+D$1*Plan1!$E$16)-D$2-D$3)*D$4 -> 7609873.9 | E10: =((Produção!E8*PreçoLivre!E10*(1-Plan1!$B$11)+E$1*Plan1!$E$16)-E$2-E$3)*E$4 -> 7089444.8 | F10: =((Produção!F8*PreçoLivre!F10*(1-Plan1!$B$11)+F$1*Plan1!$E$16)-F$2-F$3)*F$4 -> 6467364 | G10: =((Produção!G8*PreçoLivre!G10*(1-Plan1!$B$11)+G$1*Plan1!$E$16)-G$2-G$3)*G$4 -> 6026618 | H10: =((Produção!H8*PreçoLivre!H10*(1-Plan1!$B$11)+H$1*Plan1!$E$16)-H$2-H$3)*H$4 -> 5744367.4 | I10: =((Produção!I8*PreçoLivre!I10*(1-Plan1!$B$11)+I$1*Plan1!$E$16)-I$2-I$3)*I$4 -> 5280370.3 | J10: =((Produção!J8*PreçoLivre!J10*(1-Plan1!$B$11)+J$1*Plan1!$E$16)-J$2-J$3)*J$4 -> 4651495.6 | ... V10: =((Produção!V8*PreçoLivre!V10*(1-Plan1!$B$11)+V$1*Plan1!$E$16)-V$2-V$3)*V$4 -> 1271539.7
A11: =SUM(C11:W11) -> 87823538 | B11: 6 | C11: =((Produção!C9*PreçoLivre!C11*(1-Plan1!$B$11)+C$1*Plan1!$E$16)-C$2-C$3)*C$4 -> 8302854.7 | D11: =((Produção!D9*PreçoLivre!D11*(1-Plan1!$B$11)+D$1*Plan1!$E$16)-D$2-D$3)*D$4 -> 7412247 | E11: =((Produção!E9*PreçoLivre!E11*(1-Plan1!$B$11)+E$1*Plan1!$E$16)-E$2-E$3)*E$4 -> 6959956.6 | F11: =((Produção!F9*PreçoLivre!F11*(1-Plan1!$B$11)+F$1*Plan1!$E$16)-F$2-F$3)*F$4 -> 6654906.1 | G11: =((Produção!G9*PreçoLivre!G11*(1-Plan1!$B$11)+G$1*Plan1!$E$16)-G$2-G$3)*G$4 -> 5993556.9 | H11: =((Produção!H9*PreçoLivre!H11*(1-Plan1!$B$11)+H$1*Plan1!$E$16)-H$2-H$3)*H$4 -> 4925306.7 | I11: =((Produção!I9*PreçoLivre!I11*(1-Plan1!$B$11)+I$1*Plan1!$E$16)-I$2-I$3)*I$4 -> 4756645.9 | J11: =((Produção!J9*PreçoLivre!J11*(1-Plan1!$B$11)+J$1*Plan1!$E$16)-J$2-J$3)*J$4 -> 4726810.4 | ... V11: =((Produção!V9*PreçoLivre!V11*(1-Plan1!$B$11)+V$1*Plan1!$E$16)-V$2-V$3)*V$4 -> 1508849.3
A12: =SUM(C12:W12) -> 61568536 | B12: 7 | C12: =((Produção!C10*PreçoLivre!C12*(1-Plan1!$B$11)+C$1*Plan1!$E$16)-C$2-C$3)*C$4 -> 8204057.2 | D12: =((Produção!D10*PreçoLivre!D12*(1-Plan1!$B$11)+D$1*Plan1!$E$16)-D$2-D$3)*D$4 -> 6913104.1 | E12: =((Produção!E10*PreçoLivre!E12*(1-Plan1!$B$11)+E$1*Plan1!$E$16)-E$2-E$3)*E$4 -> 5713132 | F12: =((Produção!F10*PreçoLivre!F12*(1-Plan1!$B$11)+F$1*Plan1!$E$16)-F$2-F$3)*F$4 -> 5015585.8 | G12: =((Produção!G10*PreçoLivre!G12*(1-Plan1!$B$11)+G$1*Plan1!$E$16)-G$2-G$3)*G$4 -> 4171290.1 | H12: =((Produção!H10*PreçoLivre!H12*(1-Plan1!$B$11)+H$1*Plan1!$E$16)-H$2-H$3)*H$4 -> 3428907.8 | I12: =((Produção!I10*PreçoLivre!I12*(1-Plan1!$B$11)+I$1*Plan1!$E$16)-I$2-I$3)*I$4 -> 3246308.7 | J12: =((Produção!J10*PreçoLivre!J12*(1-Plan1!$B$11)+J$1*Plan1!$E$16)-J$2-J$3)*J$4 -> 2857099.5 | ... V12: =((Produção!V10*PreçoLivre!V12*(1-Plan1!$B$11)+V$1*Plan1!$E$16)-V$2-V$3)*V$4 -> 1109587.6
A13: =SUM(C13:W13) -> 76088064 | B13: 8 | C13: =((Produção!C11*PreçoLivre!C13*(1-Plan1!$B$11)+C$1*Plan1!$E$16)-C$2-C$3)*C$4 -> 8634033.1 | D13: =((Produção!D11*PreçoLivre!D13*(1-Plan1!$B$11)+D$1*Plan1!$E$16)-D$2-D$3)*D$4 -> 7440646.8 | E13: =((Produção!E11*PreçoLivre!E13*(1-Plan1!$B$11)+E$1*Plan1!$E$16)-E$2-E$3)*E$4 -> 6956415.8 | F13: =((Produção!F11*PreçoLivre!F13*(1-Plan1!$B$11)+F$1*Plan1!$E$16)-F$2-F$3)*F$4 -> 6788918.3 | G13: =((Produção!G11*PreçoLivre!G13*(1-Plan1!$B$11)+G$1*Plan1!$E$16)-G$2-G$3)*G$4 -> 5474250.3 | H13: =((Produção!H11*PreçoLivre!H13*(1-Plan1!$B$11)+H$1*Plan1!$E$16)-H$2-H$3)*H$4 -> 5562628 | I13: =((Produção!I11*PreçoLivre!I13*(1-Plan1!$B$11)+I$1*Plan1!$E$16)-I$2-I$3)*I$4 -> 4876838.5 | J13: =((Produção!J11*PreçoLivre!J13*(1-Plan1!$B$11)+J$1*Plan1!$E$16)-J$2-J$3)*J$4 -> 3953316.2 | ... V13: =((Produção!V11*PreçoLivre!V13*(1-Plan1!$B$11)+V$1*Plan1!$E$16)-V$2-V$3)*V$4 -> 1331757.7
A14: =SUM(C14:W14) -> 83839831 | B14: 9 | C14: =((Produção!C12*PreçoLivre!C14*(1-Plan1!$B$11)+C$1*Plan1!$E$16)-C$2-C$3)*C$4 -> 9083044.5 | D14: =((Produção!D12*PreçoLivre!D14*(1-Plan1!$B$11)+D$1*Plan1!$E$16)-D$2-D$3)*D$4 -> 7811978 | E14: =((Produção!E12*PreçoLivre!E14*(1-Plan1!$B$11)+E$1*Plan1!$E$16)-E$2-E$3)*E$4 -> 7023672.9 | F14: =((Produção!F12*PreçoLivre!F14*(1-Plan1!$B$11)+F$1*Plan1!$E$16)-F$2-F$3)*F$4 -> 6606690.2 | G14: =((Produção!G12*PreçoLivre!G14*(1-Plan1!$B$11)+G$1*Plan1!$E$16)-G$2-G$3)*G$4 -> 6209701.5 | H14: =((Produção!H12*PreçoLivre!H14*(1-Plan1!$B$11)+H$1*Plan1!$E$16)-H$2-H$3)*H$4 -> 5466029.4 | I14: =((Produção!I12*PreçoLivre!I14*(1-Plan1!$B$11)+I$1*Plan1!$E$16)-I$2-I$3)*I$4 -> 4795576.3 | J14: =((Produção!J12*PreçoLivre!J14*(1-Plan1!$B$11)+J$1*Plan1!$E$16)-J$2-J$3)*J$4 -> 4414882.2 | ... V14: =((Produção!V12*PreçoLivre!V14*(1-Plan1!$B$11)+V$1*Plan1!$E$16)-V$2-V$3)*V$4 -> 1525979.5
A15: =SUM(C15:W15) -> 71654914 | B15: 10 | C15: =((Produção!C13*PreçoLivre!C15*(1-Plan1!$B$11)+C$1*Plan1!$E$16)-C$2-C$3)*C$4 -> 8858414.7 | D15: =((Produção!D13*PreçoLivre!D15*(1-Plan1!$B$11)+D$1*Plan1!$E$16)-D$2-D$3)*D$4 -> 7719630.8 | E15: =((Produção!E13*PreçoLivre!E15*(1-Plan1!$B$11)+E$1*Plan1!$E$16)-E$2-E$3)*E$4 -> 6543017.5 | F15: =((Produção!F13*PreçoLivre!F15*(1-Plan1!$B$11)+F$1*Plan1!$E$16)-F$2-F$3)*F$4 -> 6015952.4 | G15: =((Produção!G13*PreçoLivre!G15*(1-Plan1!$B$11)+G$1*Plan1!$E$16)-G$2-G$3)*G$4 -> 4529352.5 | H15: =((Produção!H13*PreçoLivre!H15*(1-Plan1!$B$11)+H$1*Plan1!$E$16)-H$2-H$3)*H$4 -> 4012108.7 | I15: =((Produção!I13*PreçoLivre!I15*(1-Plan1!$B$11)+I$1*Plan1!$E$16)-I$2-I$3)*I$4 -> 3748276 | J15: =((Produção!J13*PreçoLivre!J15*(1-Plan1!$B$11)+J$1*Plan1!$E$16)-J$2-J$3)*J$4 -> 3600829.2 | ... V15: =((Produção!V13*PreçoLivre!V15*(1-Plan1!$B$11)+V$1*Plan1!$E$16)-V$2-V$3)*V$4 -> 1418272.6
A16: =SUM(C16:W16) -> 65287189 | B16: 11 | C16: =((Produção!C14*PreçoLivre!C16*(1-Plan1!$B$11)+C$1*Plan1!$E$16)-C$2-C$3)*C$4 -> 8553542 | D16: =((Produção!D14*PreçoLivre!D16*(1-Plan1!$B$11)+D$1*Plan1!$E$16)-D$2-D$3)*D$4 -> 7513979.8 | E16: =((Produção!E14*PreçoLivre!E16*(1-Plan1!$B$11)+E$1*Plan1!$E$16)-E$2-E$3)*E$4 -> 6215134.6 | F16: =((Produção!F14*PreçoLivre!F16*(1-Plan1!$B$11)+F$1*Plan1!$E$16)-F$2-F$3)*F$4 -> 5427440.3 | G16: =((Produção!G14*PreçoLivre!G16*(1-Plan1!$B$11)+G$1*Plan1!$E$16)-G$2-G$3)*G$4 -> 4641901.6 | H16: =((Produção!H14*PreçoLivre!H16*(1-Plan1!$B$11)+H$1*Plan1!$E$16)-H$2-H$3)*H$4 -> 4098449.5 | I16: =((Produção!I14*PreçoLivre!I16*(1-Plan1!$B$11)+I$1*Plan1!$E$16)-I$2-I$3)*I$4 -> 3708743.3 | J16: =((Produção!J14*PreçoLivre!J16*(1-Plan1!$B$11)+J$1*Plan1!$E$16)-J$2-J$3)*J$4 -> 3136135.3 | ... V16: =((Produção!V14*PreçoLivre!V16*(1-Plan1!$B$11)+V$1*Plan1!$E$16)-V$2-V$3)*V$4 -> 1157710.6
A17: =SUM(C17:W17) -> 72767930 | B17: 12 | C17: =((Produção!C15*PreçoLivre!C17*(1-Plan1!$B$11)+C$1*Plan1!$E$16)-C$2-C$3)*C$4 -> 8327274.1 | D17: =((Produção!D15*PreçoLivre!D17*(1-Plan1!$B$11)+D$1*Plan1!$E$16)-D$2-D$3)*D$4 -> 7347417.1 | E17: =((Produção!E15*PreçoLivre!E17*(1-Plan1!$B$11)+E$1*Plan1!$E$16)-E$2-E$3)*E$4 -> 6568161.4 | F17: =((Produção!F15*PreçoLivre!F17*(1-Plan1!$B$11)+F$1*Plan1!$E$16)-F$2-F$3)*F$4 -> 5649765.4 | G17: =((Produção!G15*PreçoLivre!G17*(1-Plan1!$B$11)+G$1*Plan1!$E$16)-G$2-G$3)*G$4 -> 5247406.5 | H17: =((Produção!H15*PreçoLivre!H17*(1-Plan1!$B$11)+H$1*Plan1!$E$16)-H$2-H$3)*H$4 -> 4770228.5 | I17: =((Produção!I15*PreçoLivre!I17*(1-Plan1!$B$11)+I$1*Plan1!$E$16)-I$2-I$3)*I$4 -> 4632139.6 | J17: =((Produção!J15*PreçoLivre!J17*(1-Plan1!$B$11)+J$1*Plan1!$E$16)-J$2-J$3)*J$4 -> 4124662.8 | ... V17: =((Produção!V15*PreçoLivre!V17*(1-Plan1!$B$11)+V$1*Plan1!$E$16)-V$2-V$3)*V$4 -> 1118757.3
... A1005: =SUM(C1005:W1005) -> 81282616 | B1005: 1000 | C1005: =((Produção!C1003*PreçoLivre!C1005*(1-Plan1!$B$11)+C$1*Plan1!$E$16)-C$2-C$3)*C$4 -> 8650341.2 | D1005: =((Produção!D1003*PreçoLivre!D1005*(1-Plan1!$B$11)+D$1*Plan1!$E$16)-D$2-D$3)*D$4 -> 7349518 | E1005: =((Produção!E1003*PreçoLivre!E1005*(1-Plan1!$B$11)+E$1*Plan1!$E$16)-E$2-E$3)*E$4 -> 6707764.5 | F1005: =((Produção!F1003*PreçoLivre!F1005*(1-Plan1!$B$11)+F$1*Plan1!$E$16)-F$2-F$3)*F$4 -> 6424532.5 | G1005: =((Produção!G1003*PreçoLivre!G1005*(1-Plan1!$B$11)+G$1*Plan1!$E$16)-G$2-G$3)*G$4 -> 5899531.4 | H1005: =((Produção!H1003*PreçoLivre!H1005*(1-Plan1!$B$11)+H$1*Plan1!$E$16)-H$2-H$3)*H$4 -> 5359022.1 | I1005: =((Produção!I1003*PreçoLivre!I1005*(1-Plan1!$B$11)+I$1*Plan1!$E$16)-I$2-I$3)*I$4 -> 4817354.5 | J1005: =((Produção!J1003*PreçoLivre!J1005*(1-Plan1!$B$11)+J$1*Plan1!$E$16)-J$2-J$3)*J$4 -> 4744989.5 | ... V1005: =((Produção!V1003*PreçoLivre!V1005*(1-Plan1!$B$11)+V$1*Plan1!$E$16)-V$2-V$3)*V$4 -> 1124825.6

Sheet VPOi
A2: PMT = JUROS + AMORTIZAÇÂO | C2: =BNDES!$H6 -> 0 | D2: =BNDES!$H7 -> 0 | E2: =BNDES!$H8 -> 0 | F2: =BNDES!$H9 -> 0 | G2: =BNDES!$H10 -> 0 | H2: =BNDES!$H11 -> 0 | I2: =BNDES!$H12 -> 0 | J2: =BNDES!$H13 -> 0 | K2: =BNDES!$H14 -> 0 | L2: =BNDES!$H15 -> 0 | M2: =BNDES!$H16 -> 0 | N2: =BNDES!$H17 -> 0 | O2: =BNDES!$H18 -> 0 | P2: =BNDES!$H19 -> 0 | Q2: =BNDES!$H20 -> 0 | R2: =BNDES!$H21 -> 0 | S2: =BNDES!$H22 -> 0 | T2: =BNDES!$H23 -> 0 | U2: =BNDES!$H24 -> 0 | V2: =BNDES!$H25 -> 0
A4: Crédito CO2 | C4: =Plan1!$E$15+Plan1!$G$15 -> 0 | D4: =C4+Plan1!$G$15 -> 0 | E4: =D4+Plan1!$G$15 -> 0 | F4: =E4+Plan1!$G$15 -> 0 | G4: =F4+Plan1!$G$15 -> 0 | H4: =G4+Plan1!$G$15 -> 0 | I4: =H4+Plan1!$G$15 -> 0 | J4: =I4+Plan1!$G$15 -> 0 | K4: =J4+Plan1!$G$15 -> 0 | ... V4: =U4+Plan1!$G$15 -> 0
A5: Manutenção | B5: =Plan1!B7 -> 500000 | C5: =B5*(1+Plan1!$G$6) -> 525000 | D5: =C5*(1+Plan1!$G$6) -> 551250 | E5: =D5*(1+Plan1!$G$6) -> 578812.5 | F5: =E5*(1+Plan1!$G$6) -> 607753.12 | G5: =F5*(1+Plan1!$G$6) -> 638140.78 | H5: =G5*(1+Plan1!$G$6) -> 670047.82 | I5: =H5*(1+Plan1!$G$6) -> 703550.21 | J5: =I5*(1+Plan1!$G$6) -> 738727.72 | ... V5: =U5*(1+Plan1!$G$6) -> 1326648.9
A7: Fator para VP | C7: =1/(1+Plan1!$E$2)^(C8) -> 0.86956522 | D7: =1/(1+Plan1!$E$2)^(D8) -> 0.75614367 | E7: =1/(1+Plan1!$E$2)^(E8) -> 0.65751623 | F7: =1/(1+Plan1!$E$2)^(F8) -> 0.57175325 | G7: =1/(1+Plan1!$E$2)^(G8) -> 0.49717674 | H7: =1/(1+Plan1!$E$2)^(H8) -> 0.4323276 | I7: =1/(1+Plan1!$E$2)^(I8) -> 0.37593704 | J7: =1/(1+Plan1!$E$2)^(J8) -> 0.32690177 | ... V7: =1/(1+Plan1!$E$2)^(V8) -> 0.061100279
B8: Valor Presente | C8: 1 | D8: 2 | E8: 3 | F8: 4 | G8: 5 | H8: 6 | I8: 7 | J8: 8 | K8: 9 | L8: 10 | M8: 11 | N8: 12 | O8: 13 | P8: 14 | Q8: 15 | R8: 16 | S8: 17 | T8: 18 | U8: 19 | V8: 20
B9: =AVERAGE(B10:B1009) -> 68820591
A10: 1 | B10: =SUM(C10:V10) -> 60943464 | C10: =((Produção!C4*(PreçoLivre!C6*(1-Plan1!$B$11)+C$4*Plan1!$E$16)-C$5-C$2)*C$7) -> 7999855.6 | D10: =((Produção!D4*(PreçoLivre!D6*(1-Plan1!$B$11)+D$4*Plan1!$E$16)-D$5-D$2)*D$7) -> 6290498.8 | E10: =((Produção!E4*(PreçoLivre!E6*(1-Plan1!$B$11)+E$4*Plan1!$E$16)-E$5-E$2)*E$7) -> 5573437 | F10: =((Produção!F4*(PreçoLivre!F6*(1-Plan1!$B$11)+F$4*Plan1!$E$16)-F$5-F$2)*F$7) -> 4845933.7 | G10: =((Produção!G4*(PreçoLivre!G6*(1-Plan1!$B$11)+G$4*Plan1!$E$16)-G$5-G$2)*G$7) -> 4020058.8 | H10: =((Produção!H4*(PreçoLivre!H6*(1-Plan1!$B$11)+H$4*Plan1!$E$16)-H$5-H$2)*H$7) -> 3697862 | I10: =((Produção!I4*(PreçoLivre!I6*(1-Plan1!$B$11)+I$4*Plan1!$E$16)-I$5-I$2)*I$7) -> 3290809.1 | J10: =((Produção!J4*(PreçoLivre!J6*(1-Plan1!$B$11)+J$4*Plan1!$E$16)-J$5-J$2)*J$7) -> 3134720 | ... V10: =((Produção!V4*(PreçoLivre!V6*(1-Plan1!$B$11)+V$4*Plan1!$E$16)-V$5-V$2)*V$7) -> 984809.87
A11: 2 | B11: =SUM(C11:V11) -> 61216059 | C11: =((Produção!C5*(PreçoLivre!C7*(1-Plan1!$B$11)+C$4*Plan1!$E$16)-C$5-C$2)*C$7) -> 7273028.7 | D11: =((Produção!D5*(PreçoLivre!D7*(1-Plan1!$B$11)+D$4*Plan1!$E$16)-D$5-D$2)*D$7) -> 6448737 | E11: =((Produção!E5*(PreçoLivre!E7*(1-Plan1!$B$11)+E$4*Plan1!$E$16)-E$5-E$2)*E$7) -> 5364663.9 | F11: =((Produção!F5*(PreçoLivre!F7*(1-Plan1!$B$11)+F$4*Plan1!$E$16)-F$5-F$2)*F$7) -> 4647396.4 | G11: =((Produção!G5*(PreçoLivre!G7*(1-Plan1!$B$11)+G$4*Plan1!$E$16)-G$5-G$2)*G$7) -> 4771395.1 | H11: =((Produção!H5*(PreçoLivre!H7*(1-Plan1!$B$11)+H$4*Plan1!$E$16)-H$5-H$2)*H$7) -> 4366177.8 | I11: =((Produção!I5*(PreçoLivre!I7*(1-Plan1!$B$11)+I$4*Plan1!$E$16)-I$5-I$2)*I$7) -> 3665265.5 | J11: =((Produção!J5*(PreçoLivre!J7*(1-Plan1!$B$11)+J$4*Plan1!$E$16)-J$5-J$2)*J$7) -> 3174191.3 | ... V11: =((Produção!V5*(PreçoLivre!V7*(1-Plan1!$B$11)+V$4*Plan1!$E$16)-V$5-V$2)*V$7) -> 920054.38
A12: 3 | B12: =SUM(C12:V12) -> 70030235 | C12: =((Produção!C6*(PreçoLivre!C8*(1-Plan1!$B$11)+C$4*Plan1!$E$16)-C$5-C$2)*C$7) -> 7531883.3 | D12: =((Produção!D6*(PreçoLivre!D8*(1-Plan1!$B$11)+D$4*Plan1!$E$16)-D$5-D$2)*D$7) -> 6568314.7 | E12: =((Produção!E6*(PreçoLivre!E8*(1-Plan1!$B$11)+E$4*Plan1!$E$16)-E$5-E$2)*E$7) -> 5497793.4 | F12: =((Produção!F6*(PreçoLivre!F8*(1-Plan1!$B$11)+F$4*Plan1!$E$16)-F$5-F$2)*F$7) -> 4854781.3 | G12: =((Produção!G6*(PreçoLivre!G8*(1-Plan1!$B$11)+G$4*Plan1!$E$16)-G$5-G$2)*G$7) -> 4678323.3 | H12: =((Produção!H6*(PreçoLivre!H8*(1-Plan1!$B$11)+H$4*Plan1!$E$16)-H$5-H$2)*H$7) -> 4620399.7 | I12: =((Produção!I6*(PreçoLivre!I8*(1-Plan1!$B$11)+I$4*Plan1!$E$16)-I$5-I$2)*I$7) -> 4305605.9 | J12: =((Produção!J6*(PreçoLivre!J8*(1-Plan1!$B$11)+J$4*Plan1!$E$16)-J$5-J$2)*J$7) -> 3790775 | ... V12: =((Produção!V6*(PreçoLivre!V8*(1-Plan1!$B$11)+V$4*Plan1!$E$16)-V$5-V$2)*V$7) -> 1305540.8
A13: 4 | B13: =SUM(C13:V13) -> 64083605 | C13: =((Produção!C7*(PreçoLivre!C9*(1-Plan1!$B$11)+C$4*Plan1!$E$16)-C$5-C$2)*C$7) -> 7706654.1 | D13: =((Produção!D7*(PreçoLivre!D9*(1-Plan1!$B$11)+D$4*Plan1!$E$16)-D$5-D$2)*D$7) -> 6507341.7 | E13: =((Produção!E7*(PreçoLivre!E9*(1-Plan1!$B$11)+E$4*Plan1!$E$16)-E$5-E$2)*E$7) -> 5597968.2 | F13: =((Produção!F7*(PreçoLivre!F9*(1-Plan1!$B$11)+F$4*Plan1!$E$16)-F$5-F$2)*F$7) -> 4682860.7 | G13: =((Produção!G7*(PreçoLivre!G9*(1-Plan1!$B$11)+G$4*Plan1!$E$16)-G$5-G$2)*G$7) -> 4578473.3 | H13: =((Produção!H7*(PreçoLivre!H9*(1-Plan1!$B$11)+H$4*Plan1!$E$16)-H$5-H$2)*H$7) -> 4265766.5 | I13: =((Produção!I7*(PreçoLivre!I9*(1-Plan1!$B$11)+I$4*Plan1!$E$16)-I$5-I$2)*I$7) -> 3866004.6 | J13: =((Produção!J7*(PreçoLivre!J9*(1-Plan1!$B$11)+J$4*Plan1!$E$16)-J$5-J$2)*J$7) -> 3360113.4 | ... V13: =((Produção!V7*(PreçoLivre!V9*(1-Plan1!$B$11)+V$4*Plan1!$E$16)-V$5-V$2)*V$7) -> 1103444.3
A14: 5 | B14: =SUM(C14:V14) -> 69213681 | C14: =((Produção!C8*(PreçoLivre!C10*(1-Plan1!$B$11)+C$4*Plan1!$E$16)-C$5-C$2)*C$7) -> 8132175 | D14: =((Produção!D8*(PreçoLivre!D10*(1-Plan1!$B$11)+D$4*Plan1!$E$16)-D$5-D$2)*D$7) -> 6617281.6 | E14: =((Produção!E8*(PreçoLivre!E10*(1-Plan1!$B$11)+E$4*Plan1!$E$16)-E$5-E$2)*E$7) -> 6164734.6 | F14: =((Produção!F8*(PreçoLivre!F10*(1-Plan1!$B$11)+F$4*Plan1!$E$16)-F$5-F$2)*F$7) -> 5623794.8 | G14: =((Produção!G8*(PreçoLivre!G10*(1-Plan1!$B$11)+G$4*Plan1!$E$16)-G$5-G$2)*G$7) -> 5240537.4 | H14: =((Produção!H8*(PreçoLivre!H10*(1-Plan1!$B$11)+H$4*Plan1!$E$16)-H$5-H$2)*H$7) -> 4995102.1 | I14: =((Produção!I8*(PreçoLivre!I10*(1-Plan1!$B$11)+I$4*Plan1!$E$16)-I$5-I$2)*I$7) -> 4591626.4 | J14: =((Produção!J8*(PreçoLivre!J10*(1-Plan1!$B$11)+J$4*Plan1!$E$16)-J$5-J$2)*J$7) -> 4044778.8 | ... V14: =((Produção!V8*(PreçoLivre!V10*(1-Plan1!$B$11)+V$4*Plan1!$E$16)-V$5-V$2)*V$7) -> 1105686.7
A15: 6 | B15: =SUM(C15:V15) -> 76368294 | C15: =((Produção!C9*(PreçoLivre!C11*(1-Plan1!$B$11)+C$4*Plan1!$E$16)-C$5-C$2)*C$7) -> 7219873.7 | D15: =((Produção!D9*(PreçoLivre!D11*(1-Plan1!$B$11)+D$4*Plan1!$E$16)-D$5-D$2)*D$7) -> 6445432.1 | E15: =((Produção!E9*(PreçoLivre!E11*(1-Plan1!$B$11)+E$4*Plan1!$E$16)-E$5-E$2)*E$7) -> 6052136.2 | F15: =((Produção!F9*(PreçoLivre!F11*(1-Plan1!$B$11)+F$4*Plan1!$E$16)-F$5-F$2)*F$7) -> 5786874.9 | G15: =((Produção!G9*(PreçoLivre!G11*(1-Plan1!$B$11)+G$4*Plan1!$E$16)-G$5-G$2)*G$7) -> 5211788.6 | H15: =((Produção!H9*(PreçoLivre!H11*(1-Plan1!$B$11)+H$4*Plan1!$E$16)-H$5-H$2)*H$7) -> 4282875.4 | I15: =((Produção!I9*(PreçoLivre!I11*(1-Plan1!$B$11)+I$4*Plan1!$E$16)-I$5-I$2)*I$7) -> 4136213.8 | J15: =((Produção!J9*(PreçoLivre!J11*(1-Plan1!$B$11)+J$4*Plan1!$E$16)-J$5-J$2)*J$7) -> 4110269.9 | ... V15: =((Produção!V9*(PreçoLivre!V11*(1-Plan1!$B$11)+V$4*Plan1!$E$16)-V$5-V$2)*V$7) -> 1312042.9
A16: 7 | B16: =SUM(C16:V16) -> 53537857 | C16: =((Produção!C10*(PreçoLivre!C12*(1-Plan1!$B$11)+C$4*Plan1!$E$16)-C$5-C$2)*C$7) -> 7133962.8 | D16: =((Produção!D10*(PreçoLivre!D12*(1-Plan1!$B$11)+D$4*Plan1!$E$16)-D$5-D$2)*D$7) -> 6011394.9 | E16: =((Produção!E10*(PreçoLivre!E12*(1-Plan1!$B$11)+E$4*Plan1!$E$16)-E$5-E$2)*E$7) -> 4967940.9 | F16: =((Produção!F10*(PreçoLivre!F12*(1-Plan1!$B$11)+F$4*Plan1!$E$16)-F$5-F$2)*F$7) -> 4361378.9 | G16: =((Produção!G10*(PreçoLivre!G12*(1-Plan1!$B$11)+G$4*Plan1!$E$16)-G$5-G$2)*G$7) -> 3627208.8 | H16: =((Produção!H10*(PreçoLivre!H12*(1-Plan1!$B$11)+H$4*Plan1!$E$16)-H$5-H$2)*H$7) -> 2981658.9 | I16: =((Produção!I10*(PreçoLivre!I12*(1-Plan1!$B$11)+I$4*Plan1!$E$16)-I$5-I$2)*I$7) -> 2822877.1 | J16: =((Produção!J10*(PreçoLivre!J12*(1-Plan1!$B$11)+J$4*Plan1!$E$16)-J$5-J$2)*J$7) -> 2484434.3 | ... V16: =((Produção!V10*(PreçoLivre!V12*(1-Plan1!$B$11)+V$4*Plan1!$E$16)-V$5-V$2)*V$7) -> 964858.75
A17: 8 | B17: =SUM(C17:V17) -> 66163534 | C17: =((Produção!C11*(PreçoLivre!C13*(1-Plan1!$B$11)+C$4*Plan1!$E$16)-C$5-C$2)*C$7) -> 7507854.9 | D17: =((Produção!D11*(PreçoLivre!D13*(1-Plan1!$B$11)+D$4*Plan1!$E$16)-D$5-D$2)*D$7) -> 6470127.7 | E17: =((Produção!E11*(PreçoLivre!E13*(1-Plan1!$B$11)+E$4*Plan1!$E$16)-E$5-E$2)*E$7) -> 6049057.2 | F17: =((Produção!F11*(PreçoLivre!F13*(1-Plan1!$B$11)+F$4*Plan1!$E$16)-F$5-F$2)*F$7) -> 5903407.2 | G17: =((Produção!G11*(PreçoLivre!G13*(1-Plan1!$B$11)+G$4*Plan1!$E$16)-G$5-G$2)*G$7) -> 4760217.6 | H17: =((Produção!H11*(PreçoLivre!H13*(1-Plan1!$B$11)+H$4*Plan1!$E$16)-H$5-H$2)*H$7) -> 4837067.9 | I17: =((Produção!I11*(PreçoLivre!I13*(1-Plan1!$B$11)+I$4*Plan1!$E$16)-I$5-I$2)*I$7) -> 4240729.1 | J17: =((Produção!J11*(PreçoLivre!J13*(1-Plan1!$B$11)+J$4*Plan1!$E$16)-J$5-J$2)*J$7) -> 3437666.2 | ... V17: =((Produção!V11*(PreçoLivre!V13*(1-Plan1!$B$11)+V$4*Plan1!$E$16)-V$5-V$2)*V$7) -> 1158050.2
A18: 9 | B18: =SUM(C18:V18) -> 72904201 | C18: =((Produção!C12*(PreçoLivre!C14*(1-Plan1!$B$11)+C$4*Plan1!$E$16)-C$5-C$2)*C$7) -> 7898299.5 | D18: =((Produção!D12*(PreçoLivre!D14*(1-Plan1!$B$11)+D$4*Plan1!$E$16)-D$5-D$2)*D$7) -> 6793024.3 | E18: =((Produção!E12*(PreçoLivre!E14*(1-Plan1!$B$11)+E$4*Plan1!$E$16)-E$5-E$2)*E$7) -> 6107541.7 | F18: =((Produção!F12*(PreçoLivre!F14*(1-Plan1!$B$11)+F$4*Plan1!$E$16)-F$5-F$2)*F$7) -> 5744948 | G18: =((Produção!G12*(PreçoLivre!G14*(1-Plan1!$B$11)+G$4*Plan1!$E$16)-G$5-G$2)*G$7) -> 5399740.4 | H18: =((Produção!H12*(PreçoLivre!H14*(1-Plan1!$B$11)+H$4*Plan1!$E$16)-H$5-H$2)*H$7) -> 4753069.1 | I18: =((Produção!I12*(PreçoLivre!I14*(1-Plan1!$B$11)+I$4*Plan1!$E$16)-I$5-I$2)*I$7) -> 4170066.3 | J18: =((Produção!J12*(PreçoLivre!J14*(1-Plan1!$B$11)+J$4*Plan1!$E$16)-J$5-J$2)*J$7) -> 3839028 | ... V18: =((Produção!V12*(PreçoLivre!V14*(1-Plan1!$B$11)+V$4*Plan1!$E$16)-V$5-V$2)*V$7) -> 1326938.7
A19: 10 | B19: =SUM(C19:V19) -> 62308621 | C19: =((Produção!C13*(PreçoLivre!C15*(1-Plan1!$B$11)+C$4*Plan1!$E$16)-C$5-C$2)*C$7) -> 7702969.3 | D19: =((Produção!D13*(PreçoLivre!D15*(1-Plan1!$B$11)+D$4*Plan1!$E$16)-D$5-D$2)*D$7) -> 6712722.4 | E19: =((Produção!E13*(PreçoLivre!E15*(1-Plan1!$B$11)+E$4*Plan1!$E$16)-E$5-E$2)*E$7) -> 5689580.4 | F19: =((Produção!F13*(PreçoLivre!F15*(1-Plan1!$B$11)+F$4*Plan1!$E$16)-F$5-F$2)*F$7) -> 5231263 | G19: =((Produção!G13*(PreçoLivre!G15*(1-Plan1!$B$11)+G$4*Plan1!$E$16)-G$5-G$2)*G$7) -> 3938567.4 | H19: =((Produção!H13*(PreçoLivre!H15*(1-Plan1!$B$11)+H$4*Plan1!$E$16)-H$5-H$2)*H$7) -> 3488790.2 | I19: =((Produção!I13*(PreçoLivre!I15*(1-Plan1!$B$11)+I$4*Plan1!$E$16)-I$5-I$2)*I$7) -> 3259370.4 | J19: =((Produção!J13*(PreçoLivre!J15*(1-Plan1!$B$11)+J$4*Plan1!$E$16)-J$5-J$2)*J$7) -> 3131155.9 | ... V19: =((Produção!V13*(PreçoLivre!V15*(1-Plan1!$B$11)+V$4*Plan1!$E$16)-V$5-V$2)*V$7) -> 1233280.5
A20: 11 | B20: =SUM(C20:V20) -> 56771469 | C20: =((Produção!C14*(PreçoLivre!C16*(1-Plan1!$B$11)+C$4*Plan1!$E$16)-C$5-C$2)*C$7) -> 7437862.6 | D20: =((Produção!D14*(PreçoLivre!D16*(1-Plan1!$B$11)+D$4*Plan1!$E$16)-D$5-D$2)*D$7) -> 6533895.4 | E20: =((Produção!E14*(PreçoLivre!E16*(1-Plan1!$B$11)+E$4*Plan1!$E$16)-E$5-E$2)*E$7) -> 5404464.8 | F20: =((Produção!F14*(PreçoLivre!F16*(1-Plan1!$B$11)+F$4*Plan1!$E$16)-F$5-F$2)*F$7) -> 4719513.3 | G20: =((Produção!G14*(PreçoLivre!G16*(1-Plan1!$B$11)+G$4*Plan1!$E$16)-G$5-G$2)*G$7) -> 4036436.2 | H20: =((Produção!H14*(PreçoLivre!H16*(1-Plan1!$B$11)+H$4*Plan1!$E$16)-H$5-H$2)*H$7) -> 3563869.2 | I20: =((Produção!I14*(PreçoLivre!I16*(1-Plan1!$B$11)+I$4*Plan1!$E$16)-I$5-I$2)*I$7) -> 3224994.2 | J20: =((Produção!J14*(PreçoLivre!J16*(1-Plan1!$B$11)+J$4*Plan1!$E$16)-J$5-J$2)*J$7) -> 2727074.2 | ... V20: =((Produção!V14*(PreçoLivre!V16*(1-Plan1!$B$11)+V$4*Plan1!$E$16)-V$5-V$2)*V$7) -> 1006704.9
A21: 12 | B21: =SUM(C21:V21) -> 63276460 | C21: =((Produção!C15*(PreçoLivre!C17*(1-Plan1!$B$11)+C$4*Plan1!$E$16)-C$5-C$2)*C$7) -> 7241107.9 | D21: =((Produção!D15*(PreçoLivre!D17*(1-Plan1!$B$11)+D$4*Plan1!$E$16)-D$5-D$2)*D$7) -> 6389058.3 | E21: =((Produção!E15*(PreçoLivre!E17*(1-Plan1!$B$11)+E$4*Plan1!$E$16)-E$5-E$2)*E$7) -> 5711444.7 | F21: =((Produção!F15*(PreçoLivre!F17*(1-Plan1!$B$11)+F$4*Plan1!$E$16)-F$5-F$2)*F$7) -> 4912839.5 | G21: =((Produção!G15*(PreçoLivre!G17*(1-Plan1!$B$11)+G$4*Plan1!$E$16)-G$5-G$2)*G$7) -> 4562962.2 | H21: =((Produção!H15*(PreçoLivre!H17*(1-Plan1!$B$11)+H$4*Plan1!$E$16)-H$5-H$2)*H$7) -> 4148024.8 | I21: =((Produção!I15*(PreçoLivre!I17*(1-Plan1!$B$11)+I$4*Plan1!$E$16)-I$5-I$2)*I$7) -> 4027947.5 | J21: =((Produção!J15*(PreçoLivre!J17*(1-Plan1!$B$11)+J$4*Plan1!$E$16)-J$5-J$2)*J$7) -> 3586663.3 | ... V21: =((Produção!V15*(PreçoLivre!V17*(1-Plan1!$B$11)+V$4*Plan1!$E$16)-V$5-V$2)*V$7) -> 972832.45
... A1009: 1000 | B1009: =SUM(C1009:V1009) -> 70680536 | C1009: =((Produção!C1003*(PreçoLivre!C1005*(1-Plan1!$B$11)+C$4*Plan1!$E$16)-C$5-C$2)*C$7) -> 7522035.9 | D1009: =((Produção!D1003*(PreçoLivre!D1005*(1-Plan1!$B$11)+D$4*Plan1!$E$16)-D$5-D$2)*D$7) -> 6390885.2 | E1009: =((Produção!E1003*(PreçoLivre!E1005*(1-Plan1!$B$11)+E$4*Plan1!$E$16)-E$5-E$2)*E$7) -> 5832838.7 | F1009: =((Produção!F1003*(PreçoLivre!F1005*(1-Plan1!$B$11)+F$4*Plan1!$E$16)-F$5-F$2)*F$7) -> 5586550 | G1009: =((Produção!G1003*(PreçoLivre!G1005*(1-Plan1!$B$11)+G$4*Plan1!$E$16)-G$5-G$2)*G$7) -> 5130027.3 | H1009: =((Produção!H1003*(PreçoLivre!H1005*(1-Plan1!$B$11)+H$4*Plan1!$E$16)-H$5-H$2)*H$7) -> 4660019.2 | I1009: =((Produção!I1003*(PreçoLivre!I1005*(1-Plan1!$B$11)+I$4*Plan1!$E$16)-I$5-I$2)*I$7) -> 4189003.9 | J1009: =((Produção!J1003*(PreçoLivre!J1005*(1-Plan1!$B$11)+J$4*Plan1!$E$16)-J$5-J$2)*J$7) -> 4126077.8 | ... V1009: =((Produção!V1003*(PreçoLivre!V1005*(1-Plan1!$B$11)+V$4*Plan1!$E$16)-V$5-V$2)*V$7) -> 978109.23

Sheet PreçoLivre
C1: =LARGE(C6:C1005,1) -> 564.41958 | D1: =LARGE(D6:D1005,1) -> 600.06783 | E1: =LARGE(E6:E1005,1) -> 663.49042 | F1: =LARGE(F6:F1005,1) -> 709.79378 | G1: =LARGE(G6:G1005,1) -> 744.60969 | H1: =LARGE(H6:H1005,1) -> 797.35972 | I1: =LARGE(I6:I1005,1) -> 832.4443 | J1: =LARGE(J6:J1005,1) -> 871.25255 | ... V1: =LARGE(V6:V1005,1) -> 1807.1356
V2: =AVERAGE(V6:V1005) -> 1363.2562
B3: Média | C3: =Plan1!E5 -> 0.05 | F3: =RAND() -> 0.98130386 | G3: =_xlfn.NORM.INV(F3,0,1) -> 2.0814549 | I3: =B6*EXP(C3-C4^2/2+_xlfn.NORM.INV(AleatLivre!B3,0,PreçoLivre!C4)) -> 528.47052 | V3: =_xlfn.STDEV.S(V6:V1005) -> 121.13192
B4: DesvPad | C4: =Plan1!E4 -> 0.02
C5: 1 | D5: 2 | E5: 3 | F5: 4 | G5: 5 | H5: 6 | I5: 7 | J5: 8 | K5: 9 | L5: 10 | M5: 11 | N5: 12 | O5: 13 | P5: 14 | Q5: 15 | R5: 16 | S5: 17 | T5: 18 | U5: 19 | V5: 20
A6: 1 | B6: =Plan1!$B$9 -> 500 | C6: =(B6*EXP($C$3-($C$4^2)/2+NORMSINV(AleatLivre!B3)*$C$4)) -> 528.47052 | D6: =(C6*EXP($C$3-($C$4^2)/2+NORMSINV(AleatLivre!C3)*$C$4)) -> 565.18959 | E6: =(D6*EXP($C$3-($C$4^2)/2+NORMSINV(AleatLivre!D3)*$C$4)) -> 589.1878 | F6: =(E6*EXP($C$3-($C$4^2)/2+NORMSINV(AleatLivre!E3)*$C$4)) -> 626.58997 | G6: =(F6*EXP($C$3-($C$4^2)/2+NORMSINV(AleatLivre!F3)*$C$4)) -> 646.60866 | H6: =(G6*EXP($C$3-($C$4^2)/2+NORMSINV(AleatLivre!G3)*$C$4)) -> 666.89991 | I6: =(H6*EXP($C$3-($C$4^2)/2+NORMSINV(AleatLivre!H3)*$C$4)) -> 684.08905 | J6: =(I6*EXP($C$3-($C$4^2)/2+NORMSINV(AleatLivre!I3)*$C$4)) -> 716.0996 | ... V6: =(U6*EXP($C$3-($C$4^2)/2+NORMSINV(AleatLivre!U3)*$C$4)) -> 1321.9464
A7: 2 | B7: =Plan1!$B$9 -> 500 | C7: =(B7*EXP($C$3-($C$4^2)/2+NORMSINV(AleatLivre!B4)*$C$4)) -> 519.12308 | D7: =(C7*EXP($C$3-($C$4^2)/2+NORMSINV(AleatLivre!C4)*$C$4)) -> 568.71951 | E7: =(D7*EXP($C$3-($C$4^2)/2+NORMSINV(AleatLivre!D4)*$C$4)) -> 574.93756 | F7: =(E7*EXP($C$3-($C$4^2)/2+NORMSINV(AleatLivre!E4)*$C$4)) -> 591.49578 | G7: =(F7*EXP($C$3-($C$4^2)/2+NORMSINV(AleatLivre!F4)*$C$4)) -> 646.98203 | H7: =(G7*EXP($C$3-($C$4^2)/2+NORMSINV(AleatLivre!G4)*$C$4)) -> 692.12998 | I7: =(H7*EXP($C$3-($C$4^2)/2+NORMSINV(AleatLivre!H4)*$C$4)) -> 717.79109 | J7: =(I7*EXP($C$3-($C$4^2)/2+NORMSINV(AleatLivre!I4)*$C$4)) -> 746.84378 | ... V7: =(U7*EXP($C$3-($C$4^2)/2+NORMSINV(AleatLivre!U4)*$C$4)) -> 1297.5778
A8: 3 | B8: =Plan1!$B$9 -> 500 | C8: =(B8*EXP($C$3-($C$4^2)/2+NORMSINV(AleatLivre!B5)*$C$4)) -> 525.15069 | D8: =(C8*EXP($C$3-($C$4^2)/2+NORMSINV(AleatLivre!C5)*$C$4)) -> 560.14837 | E8: =(D8*EXP($C$3-($C$4^2)/2+NORMSINV(AleatLivre!D5)*$C$4)) -> 593.66485 | F8: =(E8*EXP($C$3-($C$4^2)/2+NORMSINV(AleatLivre!E5)*$C$4)) -> 614.71925 | G8: =(F8*EXP($C$3-($C$4^2)/2+NORMSINV(AleatLivre!F5)*$C$4)) -> 640.90093 | H8: =(G8*EXP($C$3-($C$4^2)/2+NORMSINV(AleatLivre!G5)*$C$4)) -> 684.41292 | I8: =(H8*EXP($C$3-($C$4^2)/2+NORMSINV(AleatLivre!H5)*$C$4)) -> 698.4698 | J8: =(I8*EXP($C$3-($C$4^2)/2+NORMSINV(AleatLivre!I5)*$C$4)) -> 742.93025 | ... V8: =(U8*EXP($C$3-($C$4^2)/2+NORMSINV(AleatLivre!U5)*$C$4)) -> 1338.3544
A9: 4 | B9: =Plan1!$B$9 -> 500 | C9: =(B9*EXP($C$3-($C$4^2)/2+NORMSINV(AleatLivre!B6)*$C$4)) -> 514.25716 | D9: =(C9*EXP($C$3-($C$4^2)/2+NORMSINV(AleatLivre!C6)*$C$4)) -> 540.31675 | E9: =(D9*EXP($C$3-($C$4^2)/2+NORMSINV(AleatLivre!D6)*$C$4)) -> 552.48801 | F9: =(E9*EXP($C$3-($C$4^2)/2+NORMSINV(AleatLivre!E6)*$C$4)) -> 565.19596 | G9: =(F9*EXP($C$3-($C$4^2)/2+NORMSINV(AleatLivre!F6)*$C$4)) -> 602.7762 | H9: =(G9*EXP($C$3-($C$4^2)/2+NORMSINV(AleatLivre!G6)*$C$4)) -> 628.18193 | I9: =(H9*EXP($C$3-($C$4^2)/2+NORMSINV(AleatLivre!H6)*$C$4)) -> 655.60087 | J9: =(I9*EXP($C$3-($C$4^2)/2+NORMSINV(AleatLivre!I6)*$C$4)) -> 683.12685 | ... V9: =(U9*EXP($C$3-($C$4^2)/2+NORMSINV(AleatLivre!U6)*$C$4)) -> 1349.4302
A10: 5 | B10: =Plan1!$B$9 -> 500 | C10: =(B10*EXP($C$3-($C$4^2)/2+NORMSINV(AleatLivre!B7)*$C$4)) -> 533.63592 | D10: =(C10*EXP($C$3-($C$4^2)/2+NORMSINV(AleatLivre!C7)*$C$4)) -> 559.6469 | E10: =(D10*EXP($C$3-($C$4^2)/2+NORMSINV(AleatLivre!D7)*$C$4)) -> 591.37691 | F10: =(E10*EXP($C$3-($C$4^2)/2+NORMSINV(AleatLivre!E7)*$C$4)) -> 618.71913 | G10: =(F10*EXP($C$3-($C$4^2)/2+NORMSINV(AleatLivre!F7)*$C$4)) -> 652.02813 | H10: =(G10*EXP($C$3-($C$4^2)/2+NORMSINV(AleatLivre!G7)*$C$4)) -> 682.75324 | I10: =(H10*EXP($C$3-($C$4^2)/2+NORMSINV(AleatLivre!H7)*$C$4)) -> 701.48863 | J10: =(I10*EXP($C$3-($C$4^2)/2+NORMSINV(AleatLivre!I7)*$C$4)) -> 733.2972 | ... V10: =(U10*EXP($C$3-($C$4^2)/2+NORMSINV(AleatLivre!U7)*$C$4)) -> 1331.7344
A11: 6 | B11: =Plan1!$B$9 -> 500 | C11: =(B11*EXP($C$3-($C$4^2)/2+NORMSINV(AleatLivre!B8)*$C$4)) -> 544.74035 | D11: =(C11*EXP($C$3-($C$4^2)/2+NORMSINV(AleatLivre!C8)*$C$4)) -> 582.69507 | E11: =(D11*EXP($C$3-($C$4^2)/2+NORMSINV(AleatLivre!D8)*$C$4)) -> 610.84533 | F11: =(E11*EXP($C$3-($C$4^2)/2+NORMSINV(AleatLivre!E8)*$C$4)) -> 645.11797 | G11: =(F11*EXP($C$3-($C$4^2)/2+NORMSINV(AleatLivre!F8)*$C$4)) -> 690.69128 | H11: =(G11*EXP($C$3-($C$4^2)/2+NORMSINV(AleatLivre!G8)*$C$4)) -> 702.47435 | I11: =(H11*EXP($C$3-($C$4^2)/2+NORMSINV(AleatLivre!H8)*$C$4)) -> 773.831 | J11: =(I11*EXP($C$3-($C$4^2)/2+NORMSINV(AleatLivre!I8)*$C$4)) -> 797.96284 | ... V11: =(U11*EXP($C$3-($C$4^2)/2+NORMSINV(AleatLivre!U8)*$C$4)) -> 1417.5316
A12: 7 | B12: =Plan1!$B$9 -> 500 | C12: =(B12*EXP($C$3-($C$4^2)/2+NORMSINV(AleatLivre!B9)*$C$4)) -> 515.34544 | D12: =(C12*EXP($C$3-($C$4^2)/2+NORMSINV(AleatLivre!C9)*$C$4)) -> 547.65331 | E12: =(D12*EXP($C$3-($C$4^2)/2+NORMSINV(AleatLivre!D9)*$C$4)) -> 579.99792 | F12: =(E12*EXP($C$3-($C$4^2)/2+NORMSINV(AleatLivre!E9)*$C$4)) -> 616.66558 | G12: =(F12*EXP($C$3-($C$4^2)/2+NORMSINV(AleatLivre!F9)*$C$4)) -> 643.28252 | H12: =(G12*EXP($C$3-($C$4^2)/2+NORMSINV(AleatLivre!G9)*$C$4)) -> 657.94031 | I12: =(H12*EXP($C$3-($C$4^2)/2+NORMSINV(AleatLivre!H9)*$C$4)) -> 709.12896 | J12: =(I12*EXP($C$3-($C$4^2)/2+NORMSINV(AleatLivre!I9)*$C$4)) -> 758.19886 | ... V12: =(U12*EXP($C$3-($C$4^2)/2+NORMSINV(AleatLivre!U9)*$C$4)) -> 1411.4635
A13: 8 | B13: =Plan1!$B$9 -> 500 | C13: =(B13*EXP($C$3-($C$4^2)/2+NORMSINV(AleatLivre!B10)*$C$4)) -> 547.99508 | D13: =(C13*EXP($C$3-($C$4^2)/2+NORMSINV(AleatLivre!C10)*$C$4)) -> 564.39306 | E13: =(D13*EXP($C$3-($C$4^2)/2+NORMSINV(AleatLivre!D10)*$C$4)) -> 582.56423 | F13: =(E13*EXP($C$3-($C$4^2)/2+NORMSINV(AleatLivre!E10)*$C$4)) -> 618.11898 | G13: =(F13*EXP($C$3-($C$4^2)/2+NORMSINV(AleatLivre!F10)*$C$4)) -> 661.11492 | H13: =(G13*EXP($C$3-($C$4^2)/2+NORMSINV(AleatLivre!G10)*$C$4)) -> 691.3005 | I13: =(H13*EXP($C$3-($C$4^2)/2+NORMSINV(AleatLivre!H10)*$C$4)) -> 728.72818 | J13: =(I13*EXP($C$3-($C$4^2)/2+NORMSINV(AleatLivre!I10)*$C$4)) -> 746.73965 | ... V13: =(U13*EXP($C$3-($C$4^2)/2+NORMSINV(AleatLivre!U10)*$C$4)) -> 1359.0333
A14: 9 | B14: =Plan1!$B$9 -> 500 | C14: =(B14*EXP($C$3-($C$4^2)/2+NORMSINV(AleatLivre!B11)*$C$4)) -> 520.73713 | D14: =(C14*EXP($C$3-($C$4^2)/2+NORMSINV(AleatLivre!C11)*$C$4)) -> 557.50491 | E14: =(D14*EXP($C$3-($C$4^2)/2+NORMSINV(AleatLivre!D11)*$C$4)) -> 580.95793 | F14: =(E14*EXP($C$3-($C$4^2)/2+NORMSINV(AleatLivre!E11)*$C$4)) -> 608.65551 | G14: =(F14*EXP($C$3-($C$4^2)/2+NORMSINV(AleatLivre!F11)*$C$4)) -> 633.80096 | H14: =(G14*EXP($C$3-($C$4^2)/2+NORMSINV(AleatLivre!G11)*$C$4)) -> 672.47637 | I14: =(H14*EXP($C$3-($C$4^2)/2+NORMSINV(AleatLivre!H11)*$C$4)) -> 684.70994 | J14: =(I14*EXP($C$3-($C$4^2)/2+NORMSINV(AleatLivre!I11)*$C$4)) -> 729.56666 | ... V14: =(U14*EXP($C$3-($C$4^2)/2+NORMSINV(AleatLivre!U11)*$C$4)) -> 1276.4866
A15: 10 | B15: =Plan1!$B$9 -> 500 | C15: =(B15*EXP($C$3-($C$4^2)/2+NORMSINV(AleatLivre!B12)*$C$4)) -> 511.87573 | D15: =(C15*EXP($C$3-($C$4^2)/2+NORMSINV(AleatLivre!C12)*$C$4)) -> 536.46508 | E15: =(D15*EXP($C$3-($C$4^2)/2+NORMSINV(AleatLivre!D12)*$C$4)) -> 549.67239 | F15: =(E15*EXP($C$3-($C$4^2)/2+NORMSINV(AleatLivre!E12)*$C$4)) -> 582.42809 | G15: =(F15*EXP($C$3-($C$4^2)/2+NORMSINV(AleatLivre!F12)*$C$4)) -> 592.78727 | H15: =(G15*EXP($C$3-($C$4^2)/2+NORMSINV(AleatLivre!G12)*$C$4)) -> 614.9672 | I15: =(H15*EXP($C$3-($C$4^2)/2+NORMSINV(AleatLivre!H12)*$C$4)) -> 633.20736 | J15: =(I15*EXP($C$3-($C$4^2)/2+NORMSINV(AleatLivre!I12)*$C$4)) -> 667.30874 | ... V15: =(U15*EXP($C$3-($C$4^2)/2+NORMSINV(AleatLivre!U12)*$C$4)) -> 1268.4718
A16: 11 | B16: =Plan1!$B$9 -> 500 | C16: =(B16*EXP($C$3-($C$4^2)/2+NORMSINV(AleatLivre!B13)*$C$4)) -> 536.2349 | D16: =(C16*EXP($C$3-($C$4^2)/2+NORMSINV(AleatLivre!C13)*$C$4)) -> 564.6344 | E16: =(D16*EXP($C$3-($C$4^2)/2+NORMSINV(AleatLivre!D13)*$C$4)) -> 596.77496 | F16: =(E16*EXP($C$3-($C$4^2)/2+NORMSINV(AleatLivre!E13)*$C$4)) -> 621.14419 | G16: =(F16*EXP($C$3-($C$4^2)/2+NORMSINV(AleatLivre!F13)*$C$4)) -> 633.25696 | H16: =(G16*EXP($C$3-($C$4^2)/2+NORMSINV(AleatLivre!G13)*$C$4)) -> 663.2891 | I16: =(H16*EXP($C$3-($C$4^2)/2+NORMSINV(AleatLivre!H13)*$C$4)) -> 700.7304 | J16: =(I16*EXP($C$3-($C$4^2)/2+NORMSINV(AleatLivre!I13)*$C$4)) -> 722.7822 | ... V16: =(U16*EXP($C$3-($C$4^2)/2+NORMSINV(AleatLivre!U13)*$C$4)) -> 1388.3598
A17: 12 | B17: =Plan1!$B$9 -> 500 | C17: =(B17*EXP($C$3-($C$4^2)/2+NORMSINV(AleatLivre!B14)*$C$4)) -> 549.78521 | D17: =(C17*EXP($C$3-($C$4^2)/2+NORMSINV(AleatLivre!C14)*$C$4)) -> 557.19162 | E17: =(D17*EXP($C$3-($C$4^2)/2+NORMSINV(AleatLivre!D14)*$C$4)) -> 588.71991 | F17: =(E17*EXP($C$3-($C$4^2)/2+NORMSINV(AleatLivre!E14)*$C$4)) -> 627.46846 | G17: =(F17*EXP($C$3-($C$4^2)/2+NORMSINV(AleatLivre!F14)*$C$4)) -> 671.86099 | H17: =(G17*EXP($C$3-($C$4^2)/2+NORMSINV(AleatLivre!G14)*$C$4)) -> 703.63024 | I17: =(H17*EXP($C$3-($C$4^2)/2+NORMSINV(AleatLivre!H14)*$C$4)) -> 747.59804 | J17: =(I17*EXP($C$3-($C$4^2)/2+NORMSINV(AleatLivre!I14)*$C$4)) -> 802.2317 | ... V17: =(U17*EXP($C$3-($C$4^2)/2+NORMSINV(AleatLivre!U14)*$C$4)) -> 1427.7886
... A1005: 1000 | B1005: =Plan1!$B$9 -> 500 | C1005: =(B1005*EXP($C$3-($C$4^2)/2+NORMSINV(AleatLivre!B1002)*$C$4)) -> 520.26724 | D1005: =(C1005*EXP($C$3-($C$4^2)/2+NORMSINV(AleatLivre!C1002)*$C$4)) -> 538.99566 | E1005: =(D1005*EXP($C$3-($C$4^2)/2+NORMSINV(AleatLivre!D1002)*$C$4)) -> 566.6746 | F1005: =(E1005*EXP($C$3-($C$4^2)/2+NORMSINV(AleatLivre!E1002)*$C$4)) -> 586.1518 | G1005: =(F1005*EXP($C$3-($C$4^2)/2+NORMSINV(AleatLivre!F1002)*$C$4)) -> 602.41446 | H1005: =(G1005*EXP($C$3-($C$4^2)/2+NORMSINV(AleatLivre!G1002)*$C$4)) -> 640.73327 | I1005: =(H1005*EXP($C$3-($C$4^2)/2+NORMSINV(AleatLivre!H1002)*$C$4)) -> 667.1653 | J1005: =(I1005*EXP($C$3-($C$4^2)/2+NORMSINV(AleatLivre!I1002)*$C$4)) -> 700.5473 | ... V1005: =(U1005*EXP($C$3-($C$4^2)/2+NORMSINV(AleatLivre!U1002)*$C$4)) -> 1334.3326

Sheet Produção
B1: MENORES | C1: =SMALL(C4:C1003,1) -> 14666.429 | D1: =SMALL(D4:D1003,1) -> 13220.811 | E1: =SMALL(E4:E1003,1) -> 13176.778 | F1: =SMALL(F4:F1003,1) -> 12282.735 | G1: =SMALL(G4:G1003,1) -> 11171.944 | H1: =SMALL(H4:H1003,1) -> 10895.874 | I1: =SMALL(I4:I1003,1) -> 10390.451 | J1: =SMALL(J4:J1003,1) -> 9442.0605 | ... V1: =SMALL(V4:V1003,1) -> 7655.8766
B2: MAIORES | C2: =LARGE(C4:C1003,1) -> 21006.922 | D2: =LARGE(D4:D1003,1) -> 22943.986 | E2: =LARGE(E4:E1003,1) -> 22667.887 | F2: =LARGE(F4:F1003,1) -> 23713.233 | G2: =LARGE(G4:G1003,1) -> 22602.817 | H2: =LARGE(H4:H1003,1) -> 23830.179 | I2: =LARGE(I4:I1003,1) -> 23837.296 | J2: =LARGE(J4:J1003,1) -> 26594.605 | ... V2: =LARGE(V4:V1003,1) -> 27729.699
C3: 1 | D3: 2 | E3: 3 | F3: 4 | G3: 5 | H3: 6 | I3: 7 | J3: 8 | K3: 9 | L3: 10 | M3: 11 | N3: 12 | O3: 13 | P3: 14 | Q3: 15 | R3: 16 | S3: 17 | T3: 18 | U3: 19 | V3: 20
A4: 1 | B4: =Plan1!$B$4 -> 17520 | C4: =(B4*EXP(Plan1!$G$7-(Plan1!$G$8^2)/2+NORMSINV(AleatProd!C3)*Plan1!$G$8)) -> 18494.319 | D4: =(C4*EXP(Plan1!$G$7-(Plan1!$G$8^2)/2+NORMSINV(AleatProd!D3)*Plan1!$G$8)) -> 15773.485 | E4: =(D4*EXP(Plan1!$G$7-(Plan1!$G$8^2)/2+NORMSINV(AleatProd!E3)*Plan1!$G$8)) -> 15446.378 | F4: =(E4*EXP(Plan1!$G$7-(Plan1!$G$8^2)/2+NORMSINV(AleatProd!F3)*Plan1!$G$8)) -> 14569.282 | G4: =(F4*EXP(Plan1!$G$7-(Plan1!$G$8^2)/2+NORMSINV(AleatProd!G3)*Plan1!$G$8)) -> 13559.598 | H4: =(G4*EXP(Plan1!$G$7-(Plan1!$G$8^2)/2+NORMSINV(AleatProd!H3)*Plan1!$G$8)) -> 13899.801 | I4: =(H4*EXP(Plan1!$G$7-(Plan1!$G$8^2)/2+NORMSINV(AleatProd!I3)*Plan1!$G$8)) -> 13893.939 | J4: =(I4*EXP(Plan1!$G$7-(Plan1!$G$8^2)/2+NORMSINV(AleatProd!J3)*Plan1!$G$8)) -> 14494.921 | ... V4: =(U4*EXP(Plan1!$G$7-(Plan1!$G$8^2)/2+NORMSINV(AleatProd!V3)*Plan1!$G$8)) -> 13262.442
A5: 2 | B5: =Plan1!$B$4 -> 17520 | C5: =(B5*EXP(Plan1!$G$7-(Plan1!$G$8^2)/2+NORMSINV(AleatProd!C4)*Plan1!$G$8)) -> 17209.12 | D5: =(C5*EXP(Plan1!$G$7-(Plan1!$G$8^2)/2+NORMSINV(AleatProd!D4)*Plan1!$G$8)) -> 16045.399 | E5: =(D5*EXP(Plan1!$G$7-(Plan1!$G$8^2)/2+NORMSINV(AleatProd!E4)*Plan1!$G$8)) -> 15274.188 | F5: =(E5*EXP(Plan1!$G$7-(Plan1!$G$8^2)/2+NORMSINV(AleatProd!F4)*Plan1!$G$8)) -> 14843.687 | G5: =(F5*EXP(Plan1!$G$7-(Plan1!$G$8^2)/2+NORMSINV(AleatProd!G4)*Plan1!$G$8)) -> 15899.288 | H5: =(G5*EXP(Plan1!$G$7-(Plan1!$G$8^2)/2+NORMSINV(AleatProd!H4)*Plan1!$G$8)) -> 15637.813 | I5: =(H5*EXP(Plan1!$G$7-(Plan1!$G$8^2)/2+NORMSINV(AleatProd!I4)*Plan1!$G$8)) -> 14636.234 | J5: =(I5*EXP(Plan1!$G$7-(Plan1!$G$8^2)/2+NORMSINV(AleatProd!J4)*Plan1!$G$8)) -> 14060.714 | ... V5: =(U5*EXP(Plan1!$G$7-(Plan1!$G$8^2)/2+NORMSINV(AleatProd!V4)*Plan1!$G$8)) -> 12690.636
A6: 3 | B6: =Plan1!$B$4 -> 17520 | C6: =(B6*EXP(Plan1!$G$7-(Plan1!$G$8^2)/2+NORMSINV(AleatProd!C5)*Plan1!$G$8)) -> 17581.296 | D6: =(C6*EXP(Plan1!$G$7-(Plan1!$G$8^2)/2+NORMSINV(AleatProd!D5)*Plan1!$G$8)) -> 16574.658 | E6: =(D6*EXP(Plan1!$G$7-(Plan1!$G$8^2)/2+NORMSINV(AleatProd!E5)*Plan1!$G$8)) -> 15135.131 | F6: =(E6*EXP(Plan1!$G$7-(Plan1!$G$8^2)/2+NORMSINV(AleatProd!F5)*Plan1!$G$8)) -> 14875.927 | G6: =(F6*EXP(Plan1!$G$7-(Plan1!$G$8^2)/2+NORMSINV(AleatProd!G5)*Plan1!$G$8)) -> 15756.588 | H6: =(G6*EXP(Plan1!$G$7-(Plan1!$G$8^2)/2+NORMSINV(AleatProd!H5)*Plan1!$G$8)) -> 16677.629 | I6: =(H6*EXP(Plan1!$G$7-(Plan1!$G$8^2)/2+NORMSINV(AleatProd!I5)*Plan1!$G$8)) -> 17492.003 | J6: =(I6*EXP(Plan1!$G$7-(Plan1!$G$8^2)/2+NORMSINV(AleatProd!J5)*Plan1!$G$8)) -> 16686.33 | ... V6: =(U6*EXP(Plan1!$G$7-(Plan1!$G$8^2)/2+NORMSINV(AleatProd!V5)*Plan1!$G$8)) -> 17041.726
A7: 4 | B7: =Plan1!$B$4 -> 17520 | C7: =(B7*EXP(Plan1!$G$7-(Plan1!$G$8^2)/2+NORMSINV(AleatProd!C6)*Plan1!$G$8)) -> 18346.514 | D7: =(C7*EXP(Plan1!$G$7-(Plan1!$G$8^2)/2+NORMSINV(AleatProd!D6)*Plan1!$G$8)) -> 17033.019 | E7: =(D7*EXP(Plan1!$G$7-(Plan1!$G$8^2)/2+NORMSINV(AleatProd!E6)*Plan1!$G$8)) -> 16540.294 | F7: =(E7*EXP(Plan1!$G$7-(Plan1!$G$8^2)/2+NORMSINV(AleatProd!F6)*Plan1!$G$8)) -> 15644.693 | G7: =(F7*EXP(Plan1!$G$7-(Plan1!$G$8^2)/2+NORMSINV(AleatProd!G6)*Plan1!$G$8)) -> 16418.314 | H7: =(G7*EXP(Plan1!$G$7-(Plan1!$G$8^2)/2+NORMSINV(AleatProd!H6)*Plan1!$G$8)) -> 16858.133 | I7: =(H7*EXP(Plan1!$G$7-(Plan1!$G$8^2)/2+NORMSINV(AleatProd!I6)*Plan1!$G$8)) -> 16843.192 | J7: =(I7*EXP(Plan1!$G$7-(Plan1!$G$8^2)/2+NORMSINV(AleatProd!J6)*Plan1!$G$8)) -> 16208.93 | ... V7: =(U7*EXP(Plan1!$G$7-(Plan1!$G$8^2)/2+NORMSINV(AleatProd!V6)*Plan1!$G$8)) -> 14438.411
A8: 5 | B8: =Plan1!$B$4 -> 17520 | C8: =(B8*EXP(Plan1!$G$7-(Plan1!$G$8^2)/2+NORMSINV(AleatProd!C7)*Plan1!$G$8)) -> 18601.886 | D8: =(C8*EXP(Plan1!$G$7-(Plan1!$G$8^2)/2+NORMSINV(AleatProd!D7)*Plan1!$G$8)) -> 16705.805 | E8: =(D8*EXP(Plan1!$G$7-(Plan1!$G$8^2)/2+NORMSINV(AleatProd!E7)*Plan1!$G$8)) -> 16917.513 | F8: =(E8*EXP(Plan1!$G$7-(Plan1!$G$8^2)/2+NORMSINV(AleatProd!F7)*Plan1!$G$8)) -> 16964.542 | G8: =(F8*EXP(Plan1!$G$7-(Plan1!$G$8^2)/2+NORMSINV(AleatProd!G7)*Plan1!$G$8)) -> 17230.71 | H8: =(G8*EXP(Plan1!$G$7-(Plan1!$G$8^2)/2+NORMSINV(AleatProd!H7)*Plan1!$G$8)) -> 17993.982 | I8: =(H8*EXP(Plan1!$G$7-(Plan1!$G$8^2)/2+NORMSINV(AleatProd!I7)*Plan1!$G$8)) -> 18506.756 | J8: =(I8*EXP(Plan1!$G$7-(Plan1!$G$8^2)/2+NORMSINV(AleatProd!J7)*Plan1!$G$8)) -> 17970.459 | ... V8: =(U8*EXP(Plan1!$G$7-(Plan1!$G$8^2)/2+NORMSINV(AleatProd!V7)*Plan1!$G$8)) -> 14657.964
A9: 6 | B9: =Plan1!$B$4 -> 17520 | C9: =(B9*EXP(Plan1!$G$7-(Plan1!$G$8^2)/2+NORMSINV(AleatProd!C8)*Plan1!$G$8)) -> 16287.054 | D9: =(C9*EXP(Plan1!$G$7-(Plan1!$G$8^2)/2+NORMSINV(AleatProd!D8)*Plan1!$G$8)) -> 15653.022 | E9: =(D9*EXP(Plan1!$G$7-(Plan1!$G$8^2)/2+NORMSINV(AleatProd!E8)*Plan1!$G$8)) -> 16096.575 | F9: =(E9*EXP(Plan1!$G$7-(Plan1!$G$8^2)/2+NORMSINV(AleatProd!F8)*Plan1!$G$8)) -> 16714.692 | G9: =(F9*EXP(Plan1!$G$7-(Plan1!$G$8^2)/2+NORMSINV(AleatProd!G8)*Plan1!$G$8)) -> 16182.039 | H9: =(G9*EXP(Plan1!$G$7-(Plan1!$G$8^2)/2+NORMSINV(AleatProd!H8)*Plan1!$G$8)) -> 15131.866 | I9: =(H9*EXP(Plan1!$G$7-(Plan1!$G$8^2)/2+NORMSINV(AleatProd!I8)*Plan1!$G$8)) -> 15203.3 | J9: =(I9*EXP(Plan1!$G$7-(Plan1!$G$8^2)/2+NORMSINV(AleatProd!J8)*Plan1!$G$8)) -> 16766.486 | ... V9: =(U9*EXP(Plan1!$G$7-(Plan1!$G$8^2)/2+NORMSINV(AleatProd!V8)*Plan1!$G$8)) -> 16165.299
A10: 7 | B10: =Plan1!$B$4 -> 17520 | C10: =(B10*EXP(Plan1!$G$7-(Plan1!$G$8^2)/2+NORMSINV(AleatProd!C9)*Plan1!$G$8)) -> 17023.381 | D10: =(C10*EXP(Plan1!$G$7-(Plan1!$G$8^2)/2+NORMSINV(AleatProd!D9)*Plan1!$G$8)) -> 15601.184 | E10: =(D10*EXP(Plan1!$G$7-(Plan1!$G$8^2)/2+NORMSINV(AleatProd!E9)*Plan1!$G$8)) -> 14095.406 | F10: =(E10*EXP(Plan1!$G$7-(Plan1!$G$8^2)/2+NORMSINV(AleatProd!F9)*Plan1!$G$8)) -> 13422.54 | G10: =(F10*EXP(Plan1!$G$7-(Plan1!$G$8^2)/2+NORMSINV(AleatProd!G9)*Plan1!$G$8)) -> 12395.209 | H10: =(G10*EXP(Plan1!$G$7-(Plan1!$G$8^2)/2+NORMSINV(AleatProd!H9)*Plan1!$G$8)) -> 11558.541 | I10: =(H10*EXP(Plan1!$G$7-(Plan1!$G$8^2)/2+NORMSINV(AleatProd!I9)*Plan1!$G$8)) -> 11639.248 | J10: =(I10*EXP(Plan1!$G$7-(Plan1!$G$8^2)/2+NORMSINV(AleatProd!J9)*Plan1!$G$8)) -> 11053.264 | ... V10: =(U10*EXP(Plan1!$G$7-(Plan1!$G$8^2)/2+NORMSINV(AleatProd!V9)*Plan1!$G$8)) -> 12188.814
A11: 8 | B11: =Plan1!$B$4 -> 17520 | C11: =(B11*EXP(Plan1!$G$7-(Plan1!$G$8^2)/2+NORMSINV(AleatProd!C10)*Plan1!$G$8)) -> 16797.703 | D11: =(C11*EXP(Plan1!$G$7-(Plan1!$G$8^2)/2+NORMSINV(AleatProd!D10)*Plan1!$G$8)) -> 16218.772 | E11: =(D11*EXP(Plan1!$G$7-(Plan1!$G$8^2)/2+NORMSINV(AleatProd!E10)*Plan1!$G$8)) -> 16869.919 | F11: =(E11*EXP(Plan1!$G$7-(Plan1!$G$8^2)/2+NORMSINV(AleatProd!F10)*Plan1!$G$8)) -> 17776.17 | G11: =(F11*EXP(Plan1!$G$7-(Plan1!$G$8^2)/2+NORMSINV(AleatProd!G10)*Plan1!$G$8)) -> 15525.226 | H11: =(G11*EXP(Plan1!$G$7-(Plan1!$G$8^2)/2+NORMSINV(AleatProd!H10)*Plan1!$G$8)) -> 17240.072 | I11: =(H11*EXP(Plan1!$G$7-(Plan1!$G$8^2)/2+NORMSINV(AleatProd!I10)*Plan1!$G$8)) -> 16527.692 | J11: =(I11*EXP(Plan1!$G$7-(Plan1!$G$8^2)/2+NORMSINV(AleatProd!J10)*Plan1!$G$8)) -> 15147.426 | ... V11: =(U11*EXP(Plan1!$G$7-(Plan1!$G$8^2)/2+NORMSINV(AleatProd!V10)*Plan1!$G$8)) -> 14997.3
A12: 9 | B12: =Plan1!$B$4 -> 17520 | C12: =(B12*EXP(Plan1!$G$7-(Plan1!$G$8^2)/2+NORMSINV(AleatProd!C11)*Plan1!$G$8)) -> 18543.571 | D12: =(C12*EXP(Plan1!$G$7-(Plan1!$G$8^2)/2+NORMSINV(AleatProd!D11)*Plan1!$G$8)) -> 17188.977 | E12: =(D12*EXP(Plan1!$G$7-(Plan1!$G$8^2)/2+NORMSINV(AleatProd!E11)*Plan1!$G$8)) -> 17070.437 | F12: =(E12*EXP(Plan1!$G$7-(Plan1!$G$8^2)/2+NORMSINV(AleatProd!F11)*Plan1!$G$8)) -> 17594.927 | G12: =(F12*EXP(Plan1!$G$7-(Plan1!$G$8^2)/2+NORMSINV(AleatProd!G11)*Plan1!$G$8)) -> 18234.007 | H12: =(G12*EXP(Plan1!$G$7-(Plan1!$G$8^2)/2+NORMSINV(AleatProd!H11)*Plan1!$G$8)) -> 17432.285 | I12: =(H12*EXP(Plan1!$G$7-(Plan1!$G$8^2)/2+NORMSINV(AleatProd!I11)*Plan1!$G$8)) -> 17314.318 | J12: =(I12*EXP(Plan1!$G$7-(Plan1!$G$8^2)/2+NORMSINV(AleatProd!J11)*Plan1!$G$8)) -> 17195.314 | ... V12: =(U12*EXP(Plan1!$G$7-(Plan1!$G$8^2)/2+NORMSINV(AleatProd!V11)*Plan1!$G$8)) -> 18143.425
