Workbook

Sheet BP
D4: Balanço patrimonial da Hipotética S/A
D5: (em R$ milhões)
D7: 31 de dezembro de | H7: 31 de dezembro de
D8: 20X3 | E8: 20X2 | H8: 20X3 | I8: 20X2
C9: Ativos | G9: Passivos
C11: Ativos circulantes | G11: Passivos circulantes
C12: Caixa | D12: 211 | E12: 185 | G12: Contas a pagar | H12: 153 | I12: 125
C13: Títulos | D13: 168 | E13: 85 | G13: Títulos de curto prazo | H13: 135 | I13: 138
C14: Contas a receber | D14: 42 | E14: 50 | G14: Despesas a pagar | H14: 253 | I14: 272
C15: Estoques | D15: 315 | E15: 233
C16: Total dos ativos circulantes | D16: =SUM(D12:D15) -> 736 | E16: =SUM(E12:E15) -> 553 | G16: Total dos passivos circulantes | H16: =SUM(H12:H15) -> 541 | I16: =SUM(I12:I15) -> 535
G18: Passivos a longo prazo
C19: Ativos não circulantes | G19: Dívida a longo prazo | H19: 552 | I19: 493
C20: Terrenos e edificações | D20: 902 | E20: 833
C21: Máquinas | D21: 553 | E21: 490 | G21: Total dos passivos de longo prazo | H21: =H19 -> 552 | I21: =I19 -> 493
C22: Móveis | D22: 42 | E22: 35
C23: Depreciação Acumulada | D23: -450 | E23: -332 | G23: Patrimônio líquido
C24: Intangíveis | D24: 150 | E24: 140 | G24: Ações preferenciais | H24: 43 | I24: 28
C25: Total dos ativos não circulantes | D25: =SUM(D20:D24) -> 1197 | E25: =SUM(E20:E24) -> 1166 | G25: Ações ordinárias | H25: 57 | I25: 43
G26: Reserva de lucro | H26: 740 | I26: 620
G27: Total do patrimônio líquido | H27: =SUM(H24:H26) -> 840 | I27: =SUM(I24:I26) -> 691
C29: Total dos ativos | D29: =D16+D25 -> 1933 | E29: =E16+E25 -> 1719 | G29: Total dos passivos | H29: =H16+H21+H27 -> 1933 | I29: =I16+I21+I27 -> 1719

Sheet DRE
C2: Demonstração do resultado do exercício da Hipotética S/A
C3: (em R$ milhões)
D5: 20X3 | E5: 20X2
C6: Receita operacional bruta | D6: 3904.44 | E6: 3568.89
C7: Impostos sobre vendas | D7: =D6*0.1 -> 390.444 | E7: =E6*0.1 -> 356.889
C8: Receita operacional líquida | D8: =D6-D7 -> 3513.996 | E8: =E6-E7 -> 3212.001
C9: Custo dos produtos vendidos | D9: -2300 | E9: -2200
C10: Lucro bruto | D10: =D8+D9 -> 1213.996 | E10: =E8+E9 -> 1012.001
C12: Despesas operacionais
C13: de venda | D13: 223 | E13: 188
C14: gerais e administrativas | D14: 112 | E14: 102
C15: com aluguel | D15: 31 | E15: 27
C16: de depreciação | D16: 118 | E16: 125
C17: Total de despesas operacionais | D17: =SUM(D13:D16) -> 484 | E17: =SUM(E13:E16) -> 442
C19: Resultado operacional | D19: =D10-D17 -> 729.996 | E19: =E10-E17 -> 570.001
C21: Despesas financeiras | D21: -112 | E21: -101
C23: Lucro antes do imposto de renda | D23: =D19+D21 -> 617.996 | E23: =E19+E21 -> 469.001
C24: Imposto de renda | D24: -223 | E24: -202
C25: Lucro líquido após imposto de renda | D25: =D23+D24 -> 394.996 | E25: =E23+E24 -> 267.001
C27: Dividendos | D27: 290 | E27: 200
C28: Lucro retido | D28: =D25-D27 -> 104.996 | E28: =E25-E27 -> 67.001

Sheet Índices
C1: Dias ano | D1: 360
I3: Milhões de ações
B4: Índices | C4: 20X3 | D4: 20X2 | H4: Quantidade de ações ordinárias | I4: 40
B5: Liquidez | H5: Quantidade de ações preferenciais | I5: 60
B6: Índice de liquidez corrente | C6: =BP!D16/BP!H16 -> 1.3604436 | D6: =BP!E16/BP!I16 -> 1.0336449
B7: Índice de liquidez seca | C7: =(BP!D16-BP!D15)/BP!H16 -> 0.77818854 | D7: =(BP!E16-BP!E15)/BP!I16 -> 0.59813084 | I7: Fim 2013 | J7: Fim 2012
H8: Preço da ação ordinária (R$/unid) | I8: 38 | J8: 45
B9: Atividade | H9: Preço da ação preferencial (R$/unid) | I9: 42 | J9: 49
B10: Giro do ativo total | C10: =DRE!D8/BP!D29 -> 1.8178976 | D10: =DRE!E8/BP!E29 -> 1.8685288 | H10: Valor de mercado da dívida de longo prazo | I10: 1 | J10: 1
B11: Giro de contas a receber | C11: =DRE!D6/BP!D14 -> 92.962857 | D11: =DRE!E6/BP!E14 -> 71.3778 | H11: Valor de reposição dos ativos (milhões de R$) | I11: =BP!D29 -> 1933 | J11: =BP!E29 -> 1719
B12: Prazo médio de recebimento | C12: =D1/C11 -> 3.8725144 | D12: =D1/D11 -> 5.043585
B13: Giro de contas a pagar | C13: =-DRE!D9/BP!H12 -> 15.03268 | D13: =-DRE!E9/BP!I12 -> 17.6
B14: Prazo médio de contas a pagar | C14: =D1/C13 -> 23.947826 | D14: =D1/D13 -> 20.454545
B15: Giro de estoques | C15: =-DRE!D9/BP!D15 -> 7.3015873 | D15: =-DRE!E9/BP!E15 -> 9.4420601
B17: Endividamento | H17: Valor total ações ordinárias | I17: =I4*I8 -> 1520 | J17: =J8*I4 -> 1800
B18: Endividamento geral | C18: =(BP!H16+BP!H21)/BP!D29 -> 0.56544232 | D18: =(BP!I16+BP!I21)/BP!E29 -> 0.59802211 | H18: Valor total ações preferenciais | I18: =I5*I9 -> 2520 | J18: =J9*I5 -> 2940
B19: Cobertura de juros | C19: =DRE!D19/(-DRE!D21) -> 6.5178214 | D19: =DRE!E19/(-DRE!E21) -> 5.6435743 | H19: Valor total das ações | I19: =I17+I18 -> 4040 | J19: =J17+J18 -> 4740
B20: Passivo/Patrimônio líquido | C20: =(BP!H16+BP!H21)/BP!H27 -> 1.3011905 | D20: =(BP!I16+BP!I21)/BP!I27 -> 1.487699
B22: Rentabilidade
B23: Margem bruta | C23: =DRE!D10/DRE!D8 -> 0.3454745 | D23: =DRE!E10/DRE!E8 -> 0.31506871
B24: Margem operacional | C24: =DRE!D19/DRE!D8 -> 0.20773956 | D24: =DRE!E19/DRE!E8 -> 0.17745978
B25: Margem líquida | C25: =DRE!D25/DRE!D8 -> 0.1124065 | D25: =DRE!E25/DRE!E8 -> 0.083126064
B26: ROA (líquido) | C26: =DRE!D25/BP!D29 -> 0.20434351 | D26: =DRE!E25/BP!E29 -> 0.15532344
B27: ROA (bruto) | C27: =DRE!D19/BP!D29 -> 0.37764925 | D27: =DRE!E19/BP!E29 -> 0.33158871
B28: ROE | C28: =DRE!D25/BP!H27 -> 0.47023333 | D28: =DRE!E25/BP!I27 -> 0.38639797
B30: Valor de mercado
B31: Preço/Valor patrimonial | C31: =I19/BP!H27 -> 4.8095238 | D31: =J19/BP!I27 -> 6.8596237
B32: Q de Tobin | C32: =(I19+BP!H21*Índices!I10+BP!H16)/Índices!I11 -> 2.6554578 | D32: =(J19+BP!I21*Índices!J10+BP!I16)/Índices!J11 -> 3.3554392
B33: Índice Preço/Lucro | C33: =I19/DRE!D25 -> 10.227952 | D33: =J19/DRE!E25 -> 17.752742

Sheet IlustraCalc
A1: Solução do Exercício
A3: Índice de liquidez corrente | D3: Índice de liquidez seca | G3: Giro do ativo total
A4: Total dos ativos circulantes | B4: =BP!D16 -> 736 | D4: Caixa | E4: =BP!D12 -> 211 | G4: =DRE!C8 -> Receita operacional líquida | H4: =DRE!D8 -> 3513.996
A5: Total dos passivos circulantes | B5: =BP!H16 -> 541 | D5: Títulos | E5: =BP!D13 -> 168 | G5: =BP!C29 -> Total dos ativos | H5: =BP!D29 -> 1933
A6: IL | B6: =B4/B5 -> 1.3604436 | D6: Contas a receber | E6: =BP!D14 -> 42 | G6: GAT | H6: =H4/H5 -> 1.8178976
D7: Soma Ativos Circ-Estoque | E7: =SUM(E4:E6) -> 421
D8: Total dos passivos circulantes | E8: =BP!H16 -> 541 | G8: Prazo médio de contas a pagar
A9: Giro de contas a receber | D9: ILS | E9: =E7/E8 -> 0.77818854 | G9: GCP | H9: =E14 -> 15.03268
A10: =DRE!C6 -> Receita operacional bruta | B10: =DRE!D6 -> 3904.44 | G10: Dias/ano | H10: =Índices!D1 -> 360
A11: Contas a receber | B11: =BP!D14 -> 42 | D11: Giro de contas a pagar | G11: PMCP | H11: =H10/H9 -> 23.947826
A12: GRC | B12: =B10/B11 -> 92.962857 | D12: Custo dos produtos vendidos | E12: =-DRE!D9 -> 2300
D13: Contas a pagar | E13: =BP!H12 -> 153 | G13: Cobertura de juros
A14: Prazo médio de recebimento | D14: GCP | E14: =E12/E13 -> 15.03268 | G14: Resultado operacional | H14: =DRE!D19 -> 729.996
A15: GRC | B15: =B12 -> 92.962857 | G15: Despesas financeiras | H15: =-DRE!D21 -> 112
A16: Dias/ano | B16: =Índices!D1 -> 360 | D16: Endividamento geral | G16: ICJ | H16: =H14/H15 -> 6.5178214
A17: PMR | B17: =B16/B15 -> 3.8725144 | D17: Total dos passivos circulantes | E17: =BP!H16 -> 541
D18: Total dos passivos de longo prazo | E18: =BP!H19 -> 552 | G18: Passivo/Patrimônio líquido
A19: Giro de estoques | D19: =BP!C29 -> Total dos ativos | E19: =BP!D29 -> 1933 | G19: Total dos passivos circulantes | H19: =BP!H16 -> 541
A20: Custo dos produtos vendidos | B20: =-DRE!D9 -> 2300 | D20: EG | E20: =(E17+E18)/E19 -> 0.56544232 | G20: Total dos passivos de longo prazo | H20: =BP!H21 -> 552
A21: Estoques | B21: =BP!D15 -> 315 | G21: Passivos | H21: =H19+H20 -> 1093
A22: GE | B22: =B20/B21 -> 7.3015873 | D22: Margem bruta | G22: =BP!G23 -> Patrimônio líquido | H22: =BP!H27 -> 840
D23: =DRE!C19 -> Resultado operacional | E23: =DRE!D19 -> 729.996 | G23: IP/PL | H23: =H21/H22 -> 1.3011905
A24: Margem líquida | D24: =DRE!C8 -> Receita operacional líquida | E24: =DRE!D8 -> 3513.996
A25: Lucro líquido após imposto de renda | B25: =DRE!D25 -> 394.996 | D25: MB | E25: =E23/E24 -> 0.20773956 | G25: ROA Líquido
A26: Receita operacional líquida | B26: =DRE!D8 -> 3513.996 | G26: =DRE!C25 -> Lucro líquido após imposto de renda | H26: =DRE!D25 -> 394.996
A27: ML | B27: =B25/B26 -> 0.1124065 | D27: ROE | G27: =BP!C29 -> Total dos ativos | H27: =BP!D29 -> 1933
D28: =DRE!C25 -> Lucro líquido após imposto de renda | E28: =DRE!D25 -> 394.996 | G28: ROA Liq | H28: =H26/H27 -> 0.20434351
A29: ROA Bruto | D29: =BP!G23 -> Patrimônio líquido | E29: =BP!H27 -> 840
A30: =DRE!C19 -> Resultado operacional | B30: =DRE!D19 -> 729.996 | D30: ROE | E30: =E28/E29 -> 0.47023333 | G30: =Índices!B31 -> Preço/Valor patrimonial
A31: =BP!C29 -> Total dos ativos | B31: =BP!D29 -> 1933 | G31: =Índices!H19 -> Valor total das ações | H31: =Índices!I19 -> 4040
A32: ROA Bruto | B32: =B30/B31 -> 0.37764925 | D32: =Índices!B33 -> Índice Preço/Lucro | G32: Total do patrimônio líquido | H32: =BP!H27 -> 840
D33: =Índices!H19 -> Valor total das ações | E33: =Índices!I19 -> 4040 | G33: PVP | H33: =H31/H32 -> 4.8095238
A34: =Índices!B32 -> Q de Tobin | D34: Lucro líquido | E34: =DRE!D25 -> 394.996
A35: Valor total das ações | B35: =Índices!I19 -> 4040 | D35: P/L | E35: =E33/E34 -> 10.227952
A36: =Índices!H10 -> Valor de mercado da dívida de longo prazo | B36: =Índices!I10 -> 1
A37: Total dos passivos de longo prazo | B37: =BP!H21 -> 552
A38: Dívida de longo Prazo a mercado | B38: =B36*B37 -> 552
A39: Passivo circulante | B39: =BP!H16 -> 541
A40: Valor de mercado dos ativos | B40: =B35+B38+B39 -> 5133
A41: =Índices!H11 -> Valor de reposição dos ativos (milhões de R$) | B41: =Índices!I11 -> 1933
...

Sheet LinkDados
A4: Empresa | B4: Link
A5: Weg | B5: https://ri.weg.net/informacoes-financeiras/planilhas/
A6: Klabin | B6: https://ri.klabin.com.br/divulgacoes-e-resultados/central-de-resultados/
A7: Suzano | B7: https://ri.suzano.com.br/Portuguese/informacoes-financeiras/central-de-resultados/default.aspx
A8: Magazine Luíza | B8: https://ri.magazineluiza.com.br/Show/Planilha-de-Resultado?=BbQU+bGLTHjGnrshXKFrLw==
A9: Pão de Açucar | B9: http://www.gpari.com.br/servicos-aos-investidores/dados-operacionais-e-financeiros/
A10: Via Varejo | B10: https://ri.viavarejo.com.br/informacoes-financeiras/resultados-interativos/
A11: BRF | B11: https://ri.brf-global.com/informacoes-financeiras/planilha-de-resultados/
A12: Ambev | B12: http://ri.ambev.com.br/relatorios-publicacoes/divulgacao-de-resultados/
A13: Engie | B13: http://engie.riweb.com.br/PlanilhasDinamicas.aspx?Planilha=PD58mCikmnVW9yilpN8wvQ==
A14: Marfrig | B14: https://ri.marfrig.com.br/informacoes-financeiras/planilha-de-resultados/
A15: Usiminas | B15: http://ri.usiminas.com/informacoes-financeiras/serie-historica-de-balancos/

Sheet AlunosEmpresa
A4: Aluno | B4: Empresa | C4: Períodos
A5: 1 | B5: Weg | C5: 2009/2010
A6: 2 | B6: Weg | C6: 2011/2012
A7: 3 | B7: Weg | C7: 2013/2014
A8: 4 | B8: Weg | C8: 2015/2016
A9: 5 | B9: Weg | C9: 2017/2018
A10: 6 | B10: Weg | C10: 2019/2020
A11: 7 | B11: Klabin | C11: 2010/2011
A12: 8 | B12: Klabin | C12: 2012/2013
A13: 9 | B13: Klabin | C13: 2014/2015
A14: 10 | B14: Klabin | C14: 2016/2017
A15: 11 | B15: Klabin | C15: 2018/2019
A16: 12 | B16: Klabin | C16: 2019/2020
... A50: 46 | B50: Engie | C50: 2019/2020

Sheet Instruções
A1: Análise da empresa
A3: 1. Utilize a planilha de análise fornecida pelo professor para fazer sua avaliação de acordo com a aba Alunos/Empresa. Use a aba LiksDados
A4: 2. Se achar conveniente, visite o sítio da empresa e colete informações adicionais que você julgue necessário
A5: 3. Colete informações da empresa no sítio do Yahoo Finance (use o google). Discuta o valor do Beta da empresa
A6: 4. Compare a evolução dos preços da empresa com a evolução dos preços do Ibovespa. Use o Yahoo Finance
A7: 5. Acrescente comentários que achar pertinente sobre a situação econômico-financeira da empresa
A9: Observações: Para o valor total de capitalização de mercado, usar o sítio do Yahoo Finance
A10: Ex: digite no google: Yahho Finance Weg. Clique no link sugerido para o Yahoo Finance e veja a tela:
A36: Valor de mercado em 19/2 | D36: 174.619 | E36: bilhões | F36: Preço da ação | I36: 83.24
F37: Preço data de referência | I37: 70
F38: Valor de mercado na referência | I38: =I37/I36*D36 -> 146.84443
